Workbook

Sheet FP Units
A1: FP Units
A2: Function | B2: Complexity | C2: FPs
A3: ILF | B3: Simple | C3: 7
B4: Avarage | C4: 10
B5: Complex | C5: 15
A6: EIF | B6: Simple | C6: 5
B7: Average | C7: 7
B8: Complex | C8: 10
A9: EI | B9: Simple | C9: 3
B10: Average | C10: 4
B11: Complex | C11: 6
A12: EO | B12: Simple | C12: 4
B13: Average | C13: 5
B14: Complex | C14: 7
A15: EQ | B15: Simple | C15: 3
B16: Average | C16: 4
B17: Complex | C17: 6

Sheet Tittle
C2: Anexo 1: Cajero automatico y gestion de pedidos (CAS LAB04)
C5: COCOMO II Estimation Sheet
C10: 1 Document Information
C11: Title | D11: Anexo 1: Cajero automatico y gestion de pedidos | H11: Version | J11: 0.1
C12: Project | D12: Curso Calidad de Software | H12: Status | J12: Draft/Reviewed/Approved
C13: Client | D13: Curso Calidad de Software | H13: Type | J13: Document
C14: Rec # | D14: Christian Raul Mestas Zegarra | H14: Created | J14: 46293
C15: Author | D15: Christian Raul Mestas Zegarra | H15: Updated | J15: 46293
C17: 1.1 Revision History
C18: Ver. # | D18: Revision Date | F18: Author | G18: Distribution Date | I18: Change Ref. | J18: Brief Description
C19: 0.1 | D19: 46293 | G19: 46293
C25: 1.2 Distribution List
C26: <DevMgr>
C27: <Company Contact Person>
C28: <Project Team>
C30: 1.3 Review and Approvals
C31: Approved By / (Role) | F31: Reviewed By / (Role) | J31: Version #

Sheet Introduction
B2: Introduction
B3: TS Cocomo II based estimated sheet is a toolkit for software sizing and estimation. One can estimate the size of work using FP and SLOC. Effort is then estimated using Cocomo II. Effort can then be distributed into different project phases and the project cost is calculated. There is a Rates Sheet for selecting appropriate rate for this specific customer.
B5: FP (Function Points)
B6: Function points are a unit measure for software much like an hour is to measuring time, miles are to measuring distance or Celsius is to measuring temperature
B8: SLOC
B9: Source Line of Code, one line in a computer program. In many languages, each SLOC ends with a semicolon. SLOC is used in COCOMO as the basis for estimating software-development time.
B11: Cocomo II
B12: COCOMO is a model designed by Barry Boehm to give an estimate of the number of programmer-months it will take to develop a software product
B14: How to estimate project size using this toolkit?
B15: Pre-requisite of using this sheet is that user should have familiarity of Function Points (FP). He should be aware of FP counting rules. In the FPs sheet for each feature/component of the application estimate the count and complexity of Internal Logical Files (ILF), External Interface Files (EIF), External Inputs (EI), External Outputs (EO) and External Queries (EQ). There are 3 columns Low, Avg. and High under each category; these columns should have the count of low, average and high complexity components against each application feature. Guidelines on how to judge complexity are provided in comments of ILF, EIF and other headings at the top. Totals are automatically calculated. If there are some features in the applications which doesn't support creation of front-end or maintenance of back-end tables then FP cannot measure its size. Example of such features is any special code libraries that are invoked on schedule or through some other means to do certain functions. For such functions estimate the lines of code in SLOC sheet. Provide feature details, the programming language it will be written in and the estimated LOC count and system will automatically calculate its FPs.
B17: How to estimate effort using this toolkit?
B18: After the FPs and SLOC is estimated go to the effort sheet and estimate the scaling factors and effort multipliers. Guidelines on how to select appropriate value for an effort multiplier or the scaling factor are provided in comments of their respective description. After you have selected the appropriate values please check the consolidated size and effort estimates below. Now the effort is calculated and its time to break this effort into different phases of the project. Please set the percentages in the "Effort Distribution" sheet. Ensure that all percentage should sum to 100%. After setting the percentages please check the effort break-up in the "Effort Summary" sheet.
... B24: After the cost estimation is complete go to the "Plan sheet" to check if the project can be finished in appropriate duration. Adjust Resources, Slacks and Other Factors and then check if the estimated project duration is appropriate and feasible to the client. If the schedule is not appropriate then re-adjust resources etc to verify if the required project duration can be achieved.

Sheet FPs
E2: ILF | H2: EIF | K2: EI | N2: EO | Q2: EQ
B3: Features | C3: Comments | D3: Reference | E3: Low | F3: Avg | G3: High | H3: Low | I3: Avg | J3: High | K3: Low | L3: Avg | M3: High | N3: Low | O3: Avg | P3: High | Q3: Low | R3: Avg | S3: High | T3: Total FPs | U3: DEV Days | V3: DEV Hours | W3: Total Days
B4: Anexo 1 Parte A: cajero automatico (retiro, deposito, transferencia y consultas) | C4: 3 ILF, 2 EIF, 4 EI, 2 EO y 2 EQ de la Parte A; 76 PF | E4: 0 | F4: 3 | G4: 0 | H4: 0 | I4: 2 | J4: 0 | K4: 0 | L4: 4 | M4: 0 | N4: 0 | O4: 2 | P4: 0 | Q4: 2 | R4: 0 | S4: 0 | T4: =SUM(($E4*'FP Units'!$C$3),($F4*'FP Units'!$C$4),($G4*'FP Units'!$C$5),($H4*'FP Units'!$C$6),($I4*'FP Units'!$C$7),($J4*'FP Units'!$C$8),($K4*'FP Units'!$C$9),($L4*'FP Units'!$C$10),($M4*'FP Units'!$C$11),($N4*'FP Units'!$C$12),($O4*'FP Units'!$C$13),($P4*'FP Units'!$C$14),($Q4*'FP Units'!$C$15),($R4*'FP Units'!$C$16),($S4*'FP Units'!$C$17)) | U4: =(T4/Effort!$C$38)*'Effort Summary'!$C$5 | V4: =ROUND(U4*8,0) | W4: =(T4/Effort!$C$38)*Effort!$C$37
B5: Anexo 1 Parte B: gestion de pedidos (clientes, cuentas, productos y cobro) | C5: 3 ILF, 5 EI, 2 EO y 1 EQ de la Parte B; 63 PF | E5: 0 | F5: 3 | G5: 0 | H5: 0 | I5: 0 | J5: 0 | K5: 0 | L5: 5 | M5: 0 | N5: 0 | O5: 2 | P5: 0 | Q5: 1 | R5: 0 | S5: 0 | T5: =SUM(($E5*'FP Units'!$C$3),($F5*'FP Units'!$C$4),($G5*'FP Units'!$C$5),($H5*'FP Units'!$C$6),($I5*'FP Units'!$C$7),($J5*'FP Units'!$C$8),($K5*'FP Units'!$C$9),($L5*'FP Units'!$C$10),($M5*'FP Units'!$C$11),($N5*'FP Units'!$C$12),($O5*'FP Units'!$C$13),($P5*'FP Units'!$C$14),($Q5*'FP Units'!$C$15),($R5*'FP Units'!$C$16),($S5*'FP Units'!$C$17)) | U5: =(T5/Effort!$C$38)*'Effort Summary'!$C$5 | V5: =ROUND(U5*8,0) | W5: =(T5/Effort!$C$38)*Effort!$C$37
B6: Total Anexo 1 (Parte A + Parte B) | E6: =SUM(E4:E5) | F6: =SUM(F4:F5) | G6: =SUM(G4:G5) | H6: =SUM(H4:H5) | I6: =SUM(I4:I5) | J6: =SUM(J4:J5) | K6: =SUM(K4:K5) | L6: =SUM(L4:L5) | ... S6: =SUM(S4:S5) | U6: =SUM(U4:U5) | V6: =SUM(V4:V5) | W6: =SUM(W4:W5)
B8: Total FP | C8: =SUM(T4:T5)

Sheet SLOC
B2: Features | C2: Comments | D2: Reference | E2: Language | F2: Estimated SLOC | G2: Total FPs | H2: Dev Days | I2: Total Days
B3: Sin SLOC directo: tamano derivado de puntos de funcion del Anexo 1 | E3: Java,JSP,J2EE | F3: 0 | G3: =$F3/VLOOKUP($E3,Backfiring!$A$2:Backfiring!$B$10,2,FALSE()) | H3: =(G3/Effort!$C$38)*'Effort Summary'!$C$5 | I3: =(G3/Effort!$C$38)*Effort!$C$37
B4: Total: | F4: =SUM(F3) | G4: =SUM(G3) | H4: =(G4/Effort!$C$38)*'Effort Summary'!$C$6 | I4: =(G4/Effort!$C$38)*Effort!$C$37

Sheet Backfiring
A1: Language/Technology | B1: SLOC
A2: C++ | B2: 60
A3: C# | B3: 59
A4: Java,JSP,J2EE | B4: 60 | C4: Average of three
A5: Excel | B5: 47
A6: JavaScript | B6: 56
A7: HTML | B7: 43
A8: Visual Basic | B8: 50
A9: PLSQL/SQL | B9: 42 | C9: Average of both
A10: VB Script | B10: 45
A12: NOTE: Above Numbers are Taken from http://www.qsm.com/FPGearing.html. Average values are taken

Sheet Effort
B1: Cocomo II
B3: PM = A*Size^E*Product(All Effort Multipliers - EM)
B4: Exponent E = B+(0.01*SUM(Scaling Factors))
B6: Scaling Factors
B7: SF | C7: Description | D7: Level | E7: Value | F7: Instructions/Comments
B8: Maturity | C8: Process Maturity | D8: Nominal | E8: =VLOOKUP($D8,$B$42:$G$47,6,FALSE()) | F8: Recommended values for CMMi level 2 companies is Nominal. For Level 3 its High
B9: PREC | C9: Experience of similar Projects | D9: Low | E9: =VLOOKUP($D9,$B$42:$G$47,2,FALSE()) | F9: For Projects of new domain (that is domain we have not worked on) always select low. Select Nominal or High for projects that we are creating from scratch but we have some knowledge about domain. Select very high or extremely high for Next Releases of existing projects
B10: FLEX | C10: Flexibility required in the System | D10: Nominal | E10: =VLOOKUP($D10,$B$42:$G$47,3,FALSE()) | F10: We usually use Nominal but check comments on description for details
B11: TEAM | C11: Team Cohesiveness | D11: High | E11: =VLOOKUP($D11,$B$42:$G$47,4,FALSE()) | F11: Team Cohesiveness is always extremely high in projects where team is small and not distributed across the globe
B12: RESL | C12: Project Risk and Architectural Complexity | D12: Nominal | E12: =VLOOKUP($D12,$B$42:$G$47,5,FALSE()) | F12: We usually use Nominal but check comments on description for details
B14: Effort Multiplier EM
B15: EM | C15: Description | D15: Level | E15: Value | F15: Instructions/Comments
B16: RCPX | C16: System reliability, complexity and size indicator | D16: Very Low | E16: =VLOOKUP($D16,$B$50:$I$56,2,FALSE()) | F16: The kind of projects we have in Technosoft we normally use extra low or very low. Check comments on description for details
B17: RUSE | C17: Reusability concern with respect to current and future projects | D17: Low | E17: =VLOOKUP($D17,$B$50:$I$56,3,FALSE()) | F17: We usually use Low but check comments on description for details
B18: PDIF | C18: Platform Difficulty | D18: Very Low | E18: =VLOOKUP($D18,$B$50:$I$56,4,FALSE()) | F18: We usually use Very Low but check comments on description for details
B19: PERS | C19: Personal capability of team. Like technical capability of Programmers, Designers and testers. | D19: High | E19: =VLOOKUP($D19,$B$50:$I$56,5,FALSE()) | F19: We usually use High but check comments on description for details
B20: PREX | C20: Application, Language and tool experience | D20: High | E20: =VLOOKUP($D20,$B$50:$I$56,6,FALSE()) | F20: We usually use High but check comments on description for details
B21: FCIL | C21: Using Case tools for development etc | D21: High | E21: =VLOOKUP($D21,$B$50:$I$56,7,FALSE()) | F21: We usually use High for .NET and Nominal for java but check comments on description for details
B22: SCED | C22: Schedule Pressure | D22: Nominal | E22: =VLOOKUP($D22,$B$50:$I$56,8,FALSE()) | F22: We usually use Nominal but check comments on description for details
B24: Constants | C24: Value
B25: B | C25: 0.91
B26: B2 | C26: 1.23
B27: A | C27: 2.94
B28: E | C28: =IF((C35/1000)<1,$C$26-(0.01*SUM(E8:E12)),$C$25+(0.01*SUM(E8:E12)))
B29: EM | C29: =PRODUCT(E16:E22)
B31: Consolidated Size and Effort
B32: Technology | C32: Java,JSP,J2EE
B33: Increase due to lifecycle | C33: 0
B34: SLOC per FP | C34: =VLOOKUP($C$32,Backfiring!$A$2:Backfiring!$B$10,2,FALSE())
B35: SLOC | C35: =($C$34*FPs!$C$8)+($C$34*SLOC!$G$4)
B36: PM | C36: =($C$27*POWER(($C$35/1000),$C$28)*$C$29)*(1+$C$33)
B37: Man-days | C37: =$C$36*19
B38: FP from LOC | C38: =$C$35/$C$34
B39: Hours per FP | C39: =($C$37*8)/$C$38 | D39: Usually this number should be between 6 to 10 hours depending upon above parameters
B41: SF Scale | C41: PREC | D41: FLEX | E41: TEAM | F41: RESL | G41: Maturity
B42: Very Low | C42: 6.2 | D42: 0 | E42: 5.48 | F42: 0 | G42: 7.8
B43: Low | C43: 4.96 | D43: 1.01 | E43: 4.38 | F43: 1.41 | G43: 6.24
B44: Nominal | C44: 3.72 | D44: 2.03 | E44: 3.29 | F44: 2.83 | G44: 4.68
B45: High | C45: 2.48 | D45: 3.04 | E45: 2.19 | F45: 4.24 | G45: 3.12
B46: Very High | C46: 1.24 | D46: 4.05 | E46: 1.1 | F46: 5.65 | G46: 1.56
...

Sheet Effort Distribution
B1: Summary Units
B2: Category | C2: Percentage of Development
B3: Requirements Analysis | C3: 0.07
B4: Architecture & Design | C4: 0.07
B5: Development | C5: 0.38
B6: Customer Review Changes | C6: 0.1
B7: Test Planning | C7: 0.04 | D7: =SUM(C7:C9)
B8: Testing | C8: 0.1
B9: Bug Fixes | C9: 0.1
B10: Documentation | C10: 0 | D10: =SUM(C10:C12)
B11: Training | C11: 0
B12: Deployment | C12: 0.02
B13: Project Planning | C13: 0.02 | D13: =SUM(C13:C16)
B14: Project Monitoring | C14: 0.06
B15: CM | C15: 0.02
B16: Audits | C16: 0.02
C17: =SUM(C3:C16)
B19: NOTE: Above numbers are estimated distribution on the basis of experience and on the basis of previous projects

Sheet Effort Summary
B2: Category | C2: Effort (Days) | D2: Effort (Hours) | E2: Comments/Assumptions
B3: ='Effort Distribution'!B3 | C3: ='Effort Distribution'!$C3*Effort!$C$37 | D3: =C3*8 | E3: Requirements Analysis Hours
B4: ='Effort Distribution'!B4 | C4: ='Effort Distribution'!$C4*Effort!$C$37 | D4: =C4*8 | E4: Architecture, FS and A&D Hours
B5: ='Effort Distribution'!B5 | C5: ='Effort Distribution'!$C5*Effort!$C$37 | D5: =C5*8
B6: ='Effort Distribution'!B6 | C6: ='Effort Distribution'!$C6*Effort!$C$37 | D6: =C6*8
B7: ='Effort Distribution'!B7 | C7: ='Effort Distribution'!$C7*Effort!$C$37 | D7: =C7*8 | E7: Output are Test Plan and Test Cases
B8: ='Effort Distribution'!B8 | C8: ='Effort Distribution'!$C8*Effort!$C$37 | D8: =C8*8 | E8: Output is Test Results
B9: ='Effort Distribution'!B9 | C9: ='Effort Distribution'!$C9*Effort!$C$37 | D9: =C9*8
B10: ='Effort Distribution'!B10 | C10: ='Effort Distribution'!$C10*Effort!$C$37 | D10: =C10*8 | E10: Outputs are Deployment and Build Documents
B11: ='Effort Distribution'!B11 | C11: ='Effort Distribution'!$C11*Effort!$C$37 | D11: =C11*8
B12: ='Effort Distribution'!B12 | C12: ='Effort Distribution'!$C12*Effort!$C$37 | D12: =C12*8 | E12: Effort to deploy application
B13: ='Effort Distribution'!B13 | C13: ='Effort Distribution'!$C13*Effort!$C$37 | D13: =C13*8
B14: ='Effort Distribution'!B14 | C14: ='Effort Distribution'!$C14*Effort!$C$37 | D14: =C14*8
B15: ='Effort Distribution'!B15 | C15: ='Effort Distribution'!$C15*Effort!$C$37 | D15: =C15*8
B16: ='Effort Distribution'!B16 | C16: ='Effort Distribution'!$C16*Effort!$C$37 | D16: =C16*8
B17: Total Effort | C17: =Effort!$C$37 | D17: =SUM(D3:D16)

Sheet Cost
B1: Cost Units
B2: Units | C2: per hour | D2: per days
B3: Analista | C3: 9.4 | D3: =PRODUCT($C3,8)
B4: Desarrollador | C4: 9.4 | D4: =PRODUCT($C4,8)
B5: Probador | C5: 9.4 | D5: =PRODUCT($C5,8)
B6: Documentador | C6: 7.5 | D6: =PRODUCT($C6,8)
B7: Jefe de proyecto | C7: 11.3 | D7: =PRODUCT($C7,8)
B8: Soporte | C8: 5.6 | D8: =PRODUCT($C8,8)
B9: On-site Manager | C9: 0 | D9: =PRODUCT($C9,8)
B11: Discount | C11: Percentage: | D11: Comments (Reason for Discount):
B12: Discount by Dev Team: | C12: 0 | D12: Sin descuento de equipo: trabajo academico
B13: Discount by Sales Team: | C13: 0 | D13: Sin descuento comercial: trabajo academico
B14: Total Discount: | C14: =SUM(C12:C13)
B16: Total Project Cost
B17: Category | C17: Effort (Days) Estimated | D17: Discounted Effort for Sales | E17: Rounded Effort | F17: Effort (Hours) | G17: Cost
B18: ='Effort Summary'!B3 | C18: ='Effort Summary'!C3 | D18: =C18*(1-$C$14) | E18: =CEILING(D18,0.5) | F18: =E18*8 | G18: =PRODUCT($D18,$D3)
B19: ='Effort Summary'!B4 | C19: ='Effort Summary'!C4 | D19: =C19*(1-$C$14) | E19: =CEILING(D19,0.5) | F19: =E19*8 | G19: =PRODUCT($D19,$D3)
B20: ='Effort Summary'!B5 | C20: ='Effort Summary'!C5 | D20: =C20*(1-$C$14) | E20: =CEILING(D20,0.5) | F20: =E20*8 | G20: =PRODUCT($D20,$D4)
B21: ='Effort Summary'!B6 | C21: ='Effort Summary'!C6 | D21: =C21*(1-$C$14) | E21: =CEILING(D21,0.5) | F21: =E21*8 | G21: =PRODUCT($D21,$D4)
B22: ='Effort Summary'!B7 | C22: ='Effort Summary'!C7 | D22: =C22*(1-$C$14) | E22: =CEILING(D22,0.5) | F22: =E22*8 | G22: =PRODUCT($D22,$D5)
B23: ='Effort Summary'!B8 | C23: ='Effort Summary'!C8 | D23: =C23*(1-$C$14) | E23: =CEILING(D23,0.5) | F23: =E23*8 | G23: =PRODUCT($D23,$D6)
B24: ='Effort Summary'!B9 | C24: ='Effort Summary'!C9 | D24: =C24*(1-$C$14) | E24: =CEILING(D24,0.5) | F24: =E24*8 | G24: =PRODUCT($D24,$D4)
B25: ='Effort Summary'!B10 | C25: ='Effort Summary'!C10 | D25: =C25*(1-$C$14) | E25: =CEILING(D25,0.5) | F25: =E25*8 | G25: =PRODUCT($D25,$D7)
B26: ='Effort Summary'!B11 | C26: ='Effort Summary'!C11 | D26: =C26*(1-$C$14) | E26: =CEILING(D26,0.5) | F26: =E26*8 | G26: =PRODUCT($D26,$D3)
B27: ='Effort Summary'!B12 | C27: ='Effort Summary'!C12 | D27: =C27*(1-$C$14) | E27: =CEILING(D27,0.5) | F27: =E27*8 | G27: =PRODUCT($D27,$D3)
B28: ='Effort Summary'!B13 | C28: ='Effort Summary'!C13 | D28: =C28*(1-$C$14) | E28: =CEILING(D28,0.5) | F28: =E28*8 | G28: =PRODUCT($D28,$D$8)
B29: ='Effort Summary'!B14 | C29: ='Effort Summary'!C14 | D29: =C29*(1-$C$14) | E29: =CEILING(D29,0.5) | F29: =E29*8 | G29: =PRODUCT($D29,$D$8)
B30: ='Effort Summary'!B15 | C30: ='Effort Summary'!C15 | D30: =C30*(1-$C$14) | E30: =CEILING(D30,0.5) | F30: =E30*8 | G30: =PRODUCT($D30,$D4)
B31: ='Effort Summary'!B16 | C31: ='Effort Summary'!C16 | D31: =C31*(1-$C$14) | E31: =CEILING(D31,0.5) | F31: =E31*8 | G31: =PRODUCT($D31,$D5)
B32: Total | C32: =SUM(C18:C31) | D32: =SUM(D18:D31) | E32: =SUM(E18:E31) | F32: =SUM(F18:F31) | G32: =SUM(G18:G31)
B33: Blended Rate | G33: =($G$32/$D$32)/8
B35: Effort and Cost to Quote
B36: Category | C36: Effort (Days) | D36: Effort (Hours) | E36: Cost
B37: Analysis and Design | C37: =SUM(E18:E19) | D37: =C37*8 | E37: =SUM(G18:G19)
B38: =B20 | C38: =E20 | D38: =C38*8 | E38: =G20
B39: =B21 | C39: =E21 | D39: =C39*8 | E39: =G21
B40: Test Planning | C40: =E22 | D40: =C40*8 | E40: =G22
B41: Testing | C41: =E23 | D41: =C41*8 | E41: =G23
B42: Defect Fixation during Internal Testing | C42: =E24 | D42: =C42*8 | E42: =G24
B43: User Manuals and Install Guides | C43: =E25 | D43: =C43*8 | E43: =G25
...

Sheet Plan 1
B1: Assumptions
B2: Test Planning, Documentation and Management activities are carried out in parallel to other main activities of design, development and testing
B4: Resources | E4: Slacks
B5: Designers | C5: 1 | E5: Initial Ramp-up | F5: 1
B6: Developers | C6: 1 | E6: Deployment for testing etc | F6: 1
B7: Testers | C7: 1 | E7: Code/Peer Reviews | F7: 1
B8: Others | E8: Shipment Packaging & Review | F8: 1
B9: Comunication Delay in Analysis and Design | C9: 0.25 | E9: Total Slack | F9: =SUM(F5:F8)
B10: Possible Critical Chain Delay in Development | C10: 0.15
B11: Possible Fixation Delay in Testing | C11: 0.2
B12: Working days in a month | C12: 21
B13: Ratio of calendar days | C13: =31/C12
B15: Project Plan - Waterfall
B16: Phase | C16: Duration (days) | D16: Duration (months)
B17: Requirements/Design Phase | C17: =(Cost!$C37/$C5)*($C$9+1) | D17: =INT($C17/$C$12)&" Month "&ROUND(MOD($C17,$C$12)*$C$13,0)&" Day"
B18: Development Phase | C18: =(Cost!$C38/$C6)*($C$10+1) | D18: =INT($C18/$C$12)&" Month "&ROUND(MOD($C18,$C$12)*$C$13,0)&" Day"
B19: Testing Phase | C19: =(Cost!$C41/$C7)*($C$11+1) | D19: =INT($C19/$C$12)&" Month "&ROUND(MOD($C19,$C$12)*$C$13,0)&" Day"
B20: Total | C20: =SUM(C17:C19) | D20: =INT($C20/$C$12)&" Month "&ROUND(MOD($C20,$C$12)*$C$13,0)&" Day"
B21: Slack | C21: =$F$9
B22: Grand Total | C22: =SUM(C20:C21) | D22: =INT($C22/$C$12)&" Month "&ROUND(MOD($C22,$C$12)*$C$13,0)&" Day"
B24: Iterative Plan
B25: Iterations | C25: 2 | D25: Iteration Duration (without Slacks) | E25: Requirements/Design | F25: Development | G25: Testing
B26: 1 | C26: =IF(($C$25-$B26)<0,0,1/$C$25) | D26: =($C$20*$C26) | E26: =CEILING(($C$17/$C$20)*$D26,1) | F26: =CEILING(($C$18/$C$20)*$D26,1) | G26: =CEILING(($C$19/$C$20)*$D26,1)
B27: 2 | C27: =IF(($C$25-$B27)<0,0,1/$C$25) | D27: =($C$20*$C27) | E27: =CEILING(($C$17/$C$20)*$D27,1) | F27: =CEILING(($C$18/$C$20)*$D27,1) | G27: =CEILING(($C$19/$C$20)*$D27,1)
B28: 3 | C28: =IF(($C$25-$B28)<0,0,1/$C$25) | D28: =($C$20*$C28) | E28: =CEILING(($C$17/$C$20)*$D28,1) | F28: =CEILING(($C$18/$C$20)*$D28,1) | G28: =CEILING(($C$19/$C$20)*$D28,1)
B29: 4 | C29: =IF(($C$25-$B29)<0,0,1/$C$25) | D29: =($C$20*$C29) | E29: =CEILING(($C$17/$C$20)*$D29,1) | F29: =CEILING(($C$18/$C$20)*$D29,1) | G29: =CEILING(($C$19/$C$20)*$D29,1)
B30: 5 | C30: =IF(($C$25-$B30)<0,0,1/$C$25) | D30: =($C$20*$C30) | E30: =CEILING(($C$17/$C$20)*$D30,1) | F30: =CEILING(($C$18/$C$20)*$D30,1) | G30: =CEILING(($C$19/$C$20)*$D30,1)
B31: Total | C31: =SUM(C26:C30)

Sheet Plan 2
B1: Assumptions
B2: Test Planning, Documentation and Management activities are carried out in parallel to other main activities of design, development and testing
B4: Resources | E4: Slacks
B5: Business Analyst | C5: 1 | E5: Initial Ramp-up | F5: 1
B6: Architects & Designers | C6: 1 | E6: Deployment for testing etc | F6: 1
B7: Developers | C7: 1 | E7: Code/Peer Reviews | F7: 1
B8: Testers | C8: 1 | E8: Shipment Packaging & Review | F8: 1
B9: Others | E9: Total Slack | F9: =SUM(F4:F8)
B10: Comunication Delay in Analysis and Design | C10: 0.25
B11: Possible Critical Chain Delay in Development | C11: 0.15
B12: Possible Fixation Delay in Testing | C12: 0.2
B13: Working days in a month | C13: 21
B14: Ratio of calendar days | C14: =31/C13
B16: Project Plan - Waterfall
B17: Phase | C17: Duration (days) | D17: Duration (months)
B18: Requirements Analysis | C18: =(Cost!$E18/$C5)*($C$10+1) | D18: =INT($C18/$C$13)&" Month "&ROUND(MOD($C18,$C$13)*$C$14,0)&" Day"
B19: Design Phase | C19: =(Cost!$E19/$C6)*($C$10+1) | D19: =INT($C19/$C$13)&" Month "&ROUND(MOD($C19,$C$13)*$C$14,0)&" Day"
B20: Development Phase | C20: =(Cost!$E20/$C7)*($C$11+1) | D20: =INT($C20/$C$13)&" Month "&ROUND(MOD($C20,$C$13)*$C$14,0)&" Day"
B21: Testing Phase | C21: =(Cost!$E23/$C8)*($C$12+1) | D21: =INT($C21/$C$13)&" Month "&ROUND(MOD($C21,$C$13)*$C$14,0)&" Day"
B22: Total | C22: =SUM(C18:C21) | D22: =INT($C22/$C$13)&" Month "&ROUND(MOD($C22,$C$13)*$C$14,0)&" Day"
B23: Slack | C23: =F9
B24: Grand Total | C24: =SUM(C22:C23) | D24: =INT($C24/$C$13)&" Month "&ROUND(MOD($C24,$C$13)*$C$14,0)&" Day"
B26: Iterative Plan
B27: Iterations | C27: 3 | D27: Iteration Duration (without Slacks) | E27: Comments
B28: 1 | C28: 0.2 | D28: =ROUNDUP(C18+C19,0)+ROUNDUP($C$20*$C28,0) | E28: Includes A&D Phase plus percentage of Development Phase
B29: 2 | C29: 0.5 | D29: =ROUNDUP($C$20*$C29,0) | E29: Percentage of development phase
B30: 3 | C30: 0.3 | D30: =ROUNDUP($C$20*$C30,0)+ROUNDUP($C$21,0) | E30: Percentage of development phase and testing
B31: 4 | C31: =IF(($C$27-$B31)<0,0,1/$C$27) | D31: =($C$22*$C31) | E31: =($C$18/$C$22)*$D31
B32: 5 | C32: =IF(($C$27-$B32)<0,0,1/$C$27) | D32: =($C$22*$C32) | E32: =($C$18/$C$22)*$D32
B33: Total | C33: =SUM(C28:C32)
