Workbook

Sheet Instrucciones
A2: Plan de riesgo para la práctica 6
A4: PROPÓSITO. Identificar, evaluar y tratar riesgos de un sistema de información. Este archivo es una plantilla docente nueva basada en la estructura descrita en la práctica resuelta. No es el plan_riesgo.xls original.
A5: 1. Lea el caso resuelto en Ejemplo de análisis. No borre esas filas. Para desarrollar su trabajo utilice Activos, Cruces Activo-Amenaza y Análisis de Riesgos.
A6: 2. En Activos complete el nombre del caso, integrantes, alcance y horizonte. El caso inicial propuesto es un sistema académico ficticio. Puede conservarlo y justificar sus estimaciones o reemplazarlo por otro caso.
A7: 3. Revise los seis activos de inicio. Complete propietario, dependencias y valoración de C, I, D y A. Puede añadir activos en las filas amarillas. Use IDs únicos A1 a A20.
A8: 4. Consulte Tablas AR. Asigne P de 1 a 5 según posibilidad de ocurrencia en los próximos 12 meses e I de 1 a 5 según la consecuencia más grave. C, I, D y A significan confidencialidad, integridad, disponibilidad y autenticidad.
A9: 5. Consulte Catálogo amenazas. Los códigos T1 a T10 son locales para esta práctica y no son códigos oficiales de MAGERIT. Si necesita otra amenaza, adapte una entrada e identifique el cambio en su informe.
A10: 6. En Cruces Activo-Amenaza use una fila por escenario. Escriba un ID único R1 a R20, seleccione un activo y amenaza, describa vulnerabilidad, dimensión, controles actuales y justifique P e I. No registre todas las combinaciones posibles si no son pertinentes.
A11: 7. Un escenario válido necesita ID, activo registrado, amenaza registrada, vulnerabilidad, dimensión, controles actuales (escriba Ninguno si no hay), P, I y justificación. El estado calculado muestra lo que falta. No copie filas enteras sobre columnas azules.
A12: 8. En Análisis de Riesgos consulte resultados iniciales automáticos. El riesgo actual es P × I bajo los controles actuales declarados. Solo puede llamarse inherente si se ha evaluado sin salvaguardas. No sume índices ordinales para estimar pérdidas monetarias.
A13: 9. En el segundo bloque de Análisis de Riesgos complete tratamiento, acción concreta, responsable, plazo en días y estado. Registre evidencia real o escriba Supuesto didáctico cuando todavía sea una propuesta.
A14: 10. Asigne P residual e I residual según la eficacia justificada de las medidas. El residual es PREVISTO mientras no se implementen y prueben. Seleccionar Implementado no sustituye las evidencias. El archivo solo indica Verificado documentalmente cuando registra estado Verificado y evidencia.
... A31: ANTES DE ENTREGAR. Confirme IDs únicos, estados Listo, acciones y responsables, justificaciones de P e I, evidencias reales o supuestos identificados y decisiones. Ningún campo vacío debe interpretarse como cero riesgo.

Sheet Ejemplo de análisis
A2: Caso resuelto de gestión académica
A3: Supuestos docentes. Actual sin eficacia acreditada; residual previsto tras medidas. No es salida de PILAR.
A5: ID | B5: Activo | C5: Amenaza y debilidad | D5: P | E5: I | F5: R actual | G5: Nivel actual | H5: P resid. | I5: I resid. | J5: R resid. | K5: Nivel resid. | L5: Decisión requerida
A6: R1 | B6: Datos y respaldos | C6: Ransomware; copias accesibles | D6: 4 | E6: 5 | F6: =D6*E6 -> 20 | G6: =IF(F6<'Tablas AR'!$A$17,"Bajo",IF(F6<'Tablas AR'!$A$18,"Moderado",IF(F6<'Tablas AR'!$A$19,"Alto","Crítico"))) -> Crítico | H6: 2 | I6: 3 | J6: =H6*I6 -> 6 | K6: =IF(J6<'Tablas AR'!$A$17,"Bajo",IF(J6<'Tablas AR'!$A$18,"Moderado",IF(J6<'Tablas AR'!$A$19,"Alto","Crítico"))) -> Moderado | L6: =IF(J6<='Tablas AR'!$B$22,"Solicitar aceptación","Nuevo tratamiento") -> Nuevo tratamiento
A7: R2 | B7: Cuentas y datos | C7: Phishing; sin segundo factor | D7: 4 | E7: 4 | F7: =D7*E7 -> 16 | G7: =IF(F7<'Tablas AR'!$A$17,"Bajo",IF(F7<'Tablas AR'!$A$18,"Moderado",IF(F7<'Tablas AR'!$A$19,"Alto","Crítico"))) -> Alto | H7: 2 | I7: 3 | J7: =H7*I7 -> 6 | K7: =IF(J7<'Tablas AR'!$A$17,"Bajo",IF(J7<'Tablas AR'!$A$18,"Moderado",IF(J7<'Tablas AR'!$A$19,"Alto","Crítico"))) -> Moderado | L7: =IF(J7<='Tablas AR'!$B$22,"Solicitar aceptación","Nuevo tratamiento") -> Nuevo tratamiento
A8: R3 | B8: Datos y aplicación | C8: Alteración; permisos excesivos | D8: 4 | E8: 5 | F8: =D8*E8 -> 20 | G8: =IF(F8<'Tablas AR'!$A$17,"Bajo",IF(F8<'Tablas AR'!$A$18,"Moderado",IF(F8<'Tablas AR'!$A$19,"Alto","Crítico"))) -> Crítico | H8: 1 | I8: 5 | J8: =H8*I8 -> 5 | K8: =IF(J8<'Tablas AR'!$A$17,"Bajo",IF(J8<'Tablas AR'!$A$18,"Moderado",IF(J8<'Tablas AR'!$A$19,"Alto","Crítico"))) -> Moderado | L8: =IF(J8<='Tablas AR'!$B$22,"Solicitar aceptación","Nuevo tratamiento") -> Nuevo tratamiento
A9: R4 | B9: Infraestructura | C9: Falla eléctrica; sin UPS | D9: 3 | E9: 4 | F9: =D9*E9 -> 12 | G9: =IF(F9<'Tablas AR'!$A$17,"Bajo",IF(F9<'Tablas AR'!$A$18,"Moderado",IF(F9<'Tablas AR'!$A$19,"Alto","Crítico"))) -> Alto | H9: 2 | I9: 2 | J9: =H9*I9 -> 4 | K9: =IF(J9<'Tablas AR'!$A$17,"Bajo",IF(J9<'Tablas AR'!$A$18,"Moderado",IF(J9<'Tablas AR'!$A$19,"Alto","Crítico"))) -> Bajo | L9: =IF(J9<='Tablas AR'!$B$22,"Solicitar aceptación","Nuevo tratamiento") -> Solicitar aceptación
A10: R5 | B10: Datos y respaldos | C10: Borrado; recuperación sin pruebas | D10: 3 | E10: 4 | F10: =D10*E10 -> 12 | G10: =IF(F10<'Tablas AR'!$A$17,"Bajo",IF(F10<'Tablas AR'!$A$18,"Moderado",IF(F10<'Tablas AR'!$A$19,"Alto","Crítico"))) -> Alto | H10: 1 | I10: 3 | J10: =H10*I10 -> 3 | K10: =IF(J10<'Tablas AR'!$A$17,"Bajo",IF(J10<'Tablas AR'!$A$18,"Moderado",IF(J10<'Tablas AR'!$A$19,"Alto","Crítico"))) -> Bajo | L10: =IF(J10<='Tablas AR'!$B$22,"Solicitar aceptación","Nuevo tratamiento") -> Solicitar aceptación
A11: R6 | B11: Datos y cuentas | C11: Divulgación; enlaces abiertos | D11: 3 | E11: 5 | F11: =D11*E11 -> 15 | G11: =IF(F11<'Tablas AR'!$A$17,"Bajo",IF(F11<'Tablas AR'!$A$18,"Moderado",IF(F11<'Tablas AR'!$A$19,"Alto","Crítico"))) -> Alto | H11: 1 | I11: 5 | J11: =H11*I11 -> 5 | K11: =IF(J11<'Tablas AR'!$A$17,"Bajo",IF(J11<'Tablas AR'!$A$18,"Moderado",IF(J11<'Tablas AR'!$A$19,"Alto","Crítico"))) -> Moderado | L11: =IF(J11<='Tablas AR'!$B$22,"Solicitar aceptación","Nuevo tratamiento") -> Nuevo tratamiento
A14: ID | B14: Tratamiento | C14: Acción concreta | D14: Responsable | E14: Plazo días
A15: R1 | B15: Mitigar | C15: Copias aisladas y ensayo de recuperación | D15: Administrador TI | E15: 30
A16: R2 | B16: Mitigar | C16: Segundo factor y entrenamiento | D16: Seguridad TI | E16: 15
A17: R3 | B17: Mitigar | C17: Permisos por rol, aprobación y bitácora | D17: Desarrollo | E17: 20
A18: R4 | B18: Mitigar | C18: UPS y apagado controlado | D18: Infraestructura | E18: 30
A19: R5 | B19: Mitigar | C19: Versionado y prueba de restauración | D19: Administrador datos | E19: 15
A20: R6 | B20: Mitigar | C20: Acceso mínimo y bloquear enlaces públicos | D20: Responsable datos | E20: 15
A23: Lectura R3: 4 × 5 = 20 crítico. Con controles: 1 × 5 = 5 moderado. La gravedad sigue siendo 5.
A25: R3 y R6 requieren revisión directiva por I = 5. Una reducción de probabilidad no recupera confidencialidad perdida.
A27: Comprobación manual R1: 20 a 6. Reducción del índice ordinal = (20 − 6) / 20 = 70 %.

Sheet Tablas AR
A2: Criterios de evaluación para 12 meses
A4: P | B4: Nivel | C4: Probabilidad del evento en 12 meses
A5: 1 | B5: Rara | C5: Hasta 5 %
A6: 2 | B6: Poco probable | C6: Mayor de 5 % hasta 20 %
A7: 3 | B7: Posible | C7: Mayor de 20 % hasta 50 %
A8: 4 | B8: Probable | C8: Mayor de 50 % hasta 80 %
A9: 5 | B9: Muy probable | C9: Mayor de 80 %
A10: I | B10: Nivel | C10: Consecuencia más grave aplicable
A11: 1 | B11: Menor | C11: Menos de 1 h de interrupción. Sin afectación relevante de datos.
A12: 2 | B12: Baja | C12: De 1 a menos de 4 h. Corrección local y recuperable.
A13: 3 | B13: Media | C13: De 4 a menos de 8 h o corrección importante de registros.
A14: 4 | B14: Alta | C14: De 8 a 24 h o alteración relevante de registros.
A15: 5 | B15: Muy alta | C15: Más de 24 h o alteración o divulgación masiva de datos.
A16: Desde R | B16: Clasificación | C16: Respuesta docente
A17: 5 | B17: Moderado | C17: Tratar y revisar
A18: 10 | B18: Alto | C18: Priorizar tratamiento
A19: 17 | B19: Crítico | C19: Atención urgente
A20: 1 | B20: Bajo | C20: Proponer aceptación documentada
A22: Máximo aceptable | B22: 4
A24: Dimensión | B24: Significado | C24: Ejemplo de consecuencia
A25: C | B25: Confidencialidad | C25: Lectura de datos por personas no autorizadas
A26: I | B26: Integridad | C26: Notas incompletas o alteradas
A27: D | B27: Disponibilidad | C27: Servicio de matrícula interrumpido
A28: A | B28: Autenticidad | C28: Operación atribuida a un usuario suplantado
A30: Regla | B30: Escala ordinal | C30: No corresponde a valores monetarios ni al cálculo completo de PILAR
A31: Criterio I | B31: Máximo efecto | C31: Si ocurre cualquiera de los efectos de un nivel, considere ese nivel

Sheet Catálogo amenazas
A2: Amenazas y vulnerabilidades de referencia
A4: Código | B4: Amenaza | C4: Tipo | D4: Vulnerabilidad posible | E4: Medida posible
A5: T1 | B5: Ransomware | C5: Ataque | D5: Copias accesibles desde producción | E5: Copias aisladas y restauración probada
A6: T2 | B6: Phishing | C6: Ataque | D6: Acceso sin segundo factor | E6: Segundo factor y entrenamiento
A7: T3 | B7: Alteración de notas | C7: Abuso o error | D7: Permisos excesivos | E7: Permisos por rol y aprobación
A8: T4 | B8: Falla eléctrica | C8: Falla técnica | D8: Ausencia de respaldo eléctrico | E8: UPS y apagado controlado
A9: T5 | B9: Borrado accidental | C9: Error humano | D9: Restauración no ensayada | E9: Versionado y ensayo de recuperación
A10: T6 | B10: Divulgación de datos | C10: Abuso o error | D10: Archivos compartidos sin restricción | E10: Acceso mínimo y revisión de enlaces
A11: T7 | B11: Falla del servidor | C11: Falla técnica | D11: Sin redundancia ni mantenimiento | E11: Mantenimiento y plan de recuperación
A12: T8 | B12: Pérdida de conectividad | C12: Falla técnica | D12: Un solo enlace | E12: Enlace alternativo y procedimiento manual
A13: T9 | B13: Robo de equipo | C13: Ataque físico | D13: Equipo portátil sin cifrado | E13: Cifrado y control físico
A14: T10 | B14: Error de actualización | C14: Error técnico | D14: Cambios sin prueba ni reversión | E14: Pruebas previas y plan de reversión

Sheet Activos
A2: Inventario y contexto del caso
A4: Caso | B4: Sistema académico ficticio
A5: Integrantes | B5: Christian Raul Mestas Zegarra
A6: Alcance | B6: Matrícula, notas y consulta
A7: Horizonte | B7: Próximos 12 meses
A9: ID | B9: Nombre del activo | C9: Tipo | D9: Propietario | E9: Depende de IDs | F9: C 1–5 | G9: I 1–5 | H9: D 1–5 | I9: A 1–5 | J9: Justificación del valor
A10: A1 | B10: Servicio académico | C10: Servicio | D10: Dirección Académica | E10: A2, A3, A4 | F10: 3 | G10: 4 | H10: 5 | I10: 3 | J10: Matrícula y consulta sostienen OBJ-02; D5 por interrupción del servicio; I4 por notas (traza FR-09, FR-05)
A11: A2 | B11: Datos académicos | C11: Datos | D11: Secretaría Académica | E11: A4, A6 | F11: 5 | G11: 5 | H11: 4 | I11: 4 | J11: Estudiantes, matrículas, notas y pagos (IRQ-01–IRQ-07); C5/I5 por datos personales y notas oficiales
A12: A3 | B12: Aplicación web | C12: Software | D12: Administración del Sistema | E12: A4, A6 | F12: 4 | G12: 4 | H12: 4 | I12: 5 | J12: RBAC y bloqueo (FR-15–FR-19, FR-18); A5 por operaciones atribuibles a suplantados
A13: A4 | B13: Servidor y red | C13: Infraestructura | D13: Infraestructura TI | E13: A6 | F13: 2 | G13: 3 | H13: 5 | I13: 2 | J13: Base de A1–A3 y A5; D5 por corte total del servicio
A14: A5 | B14: Respaldos | C14: Recuperación | D14: Administrador TI | E14: A4, A6 | F14: 5 | G14: 5 | H14: 3 | I14: 2 | J14: Copia íntegra de datos académicos con RPO 24 h / RTO 4 h (NFR-10)
A15: A6 | B15: Personal y cuentas | C15: Personas | D15: Administración del Sistema | F15: 4 | G15: 3 | H15: 2 | I15: 5 | J15: Cuentas y credenciales (FR-16, FR-18); A5 por autenticidad de operaciones

Sheet Cruces Activo-Amenaza
A2: Escenarios del alumno
A3: Complete amarillo. Azul calcula. Una fila corresponde a un escenario, no a todos los activos simultáneamente.
A5: ID riesgo | B5: ID activo | C5: Activo automático | D5: ID amenaza | E5: Amenaza automática | F5: Vulnerabilidad concreta | G5: Dimensión | H5: Controles actuales | I5: P 1–5 | J5: I 1–5 | K5: Justificación de P e I | L5: Estado del registro
A6: R1 | B6: A5 | C6: =IF(B6="","",IF(COUNTIF(Activos!$A$10:$A$29,B6)<>1,"ID activo inválido",IF(COUNTIFS(Activos!$A$10:$A$29,B6,Activos!$B$10:$B$29,"<>")<>1,"Falta nombre",VLOOKUP(B6,Activos!$A$10:$B$29,2,FALSE)))) | D6: T1 | E6: =IF(D6="","",IF(COUNTIF('Catálogo amenazas'!$A$5:$A$14,D6)<>1,"ID amenaza inválido",VLOOKUP(D6,'Catálogo amenazas'!$A$5:$B$14,2,FALSE))) | F6: Copias de respaldo accesibles desde el servidor de producción | G6: D | H6: Ninguno | I6: 3 | J6: 5 | K6: P3: ransomware 20–50% anual sin copias aisladas. I5: cifrado total deja matrícula y notas fuera >24 h | L6: =IF(COUNTA(A6:B6,D6,F6:K6)=0,"",IF(A6="","Falta ID riesgo",IF(COUNTIF($A$6:$A$25,A6)<>1,"ID riesgo duplicado",IF(OR(B6="",C6="ID activo inválido",C6="Falta nombre"),"Revisar activo",IF(OR(D6="",E6="ID amenaza inválido"),"Revisar amenaza",IF(OR(F6="",G6="",H6="",K6=""),"Falta descripción o justificación",IF(OR(COUNT(I6:J6)<>2,I6<1,I6>5,J6<1,J6>5,MOD(I6,1)<>0,MOD(J6,1)<>0),"P e I deben ser enteros 1–5","Listo")))))))
A7: R2 | B7: A6 | C7: =IF(B7="","",IF(COUNTIF(Activos!$A$10:$A$29,B7)<>1,"ID activo inválido",IF(COUNTIFS(Activos!$A$10:$A$29,B7,Activos!$B$10:$B$29,"<>")<>1,"Falta nombre",VLOOKUP(B7,Activos!$A$10:$B$29,2,FALSE)))) | D7: T2 | E7: =IF(D7="","",IF(COUNTIF('Catálogo amenazas'!$A$5:$A$14,D7)<>1,"ID amenaza inválido",VLOOKUP(D7,'Catálogo amenazas'!$A$5:$B$14,2,FALSE))) | F7: Cuentas de personal sin segundo factor | G7: C | H7: Ninguno | I7: 4 | J7: 4 | K7: P4: phishing masivo supera 50% anual. I4: sesión suplantada exige corrección de 8–24 h | L7: =IF(COUNTA(A7:B7,D7,F7:K7)=0,"",IF(A7="","Falta ID riesgo",IF(COUNTIF($A$6:$A$25,A7)<>1,"ID riesgo duplicado",IF(OR(B7="",C7="ID activo inválido",C7="Falta nombre"),"Revisar activo",IF(OR(D7="",E7="ID amenaza inválido"),"Revisar amenaza",IF(OR(F7="",G7="",H7="",K7=""),"Falta descripción o justificación",IF(OR(COUNT(I7:J7)<>2,I7<1,I7>5,J7<1,J7>5,MOD(I7,1)<>0,MOD(J7,1)<>0),"P e I deben ser enteros 1–5","Listo")))))))
A8: R3 | B8: A2 | C8: =IF(B8="","",IF(COUNTIF(Activos!$A$10:$A$29,B8)<>1,"ID activo inválido",IF(COUNTIFS(Activos!$A$10:$A$29,B8,Activos!$B$10:$B$29,"<>")<>1,"Falta nombre",VLOOKUP(B8,Activos!$A$10:$B$29,2,FALSE)))) | D8: T3 | E8: =IF(D8="","",IF(COUNTIF('Catálogo amenazas'!$A$5:$A$14,D8)<>1,"ID amenaza inválido",VLOOKUP(D8,'Catálogo amenazas'!$A$5:$B$14,2,FALSE))) | F8: Permisos excesivos sobre notas sin aprobación | G8: I | H8: Ninguno | I8: 3 | J8: 5 | K8: P3: abuso interno 20–50% con permisos amplios. I5: alteración masiva invalida actas oficiales | L8: =IF(COUNTA(A8:B8,D8,F8:K8)=0,"",IF(A8="","Falta ID riesgo",IF(COUNTIF($A$6:$A$25,A8)<>1,"ID riesgo duplicado",IF(OR(B8="",C8="ID activo inválido",C8="Falta nombre"),"Revisar activo",IF(OR(D8="",E8="ID amenaza inválido"),"Revisar amenaza",IF(OR(F8="",G8="",H8="",K8=""),"Falta descripción o justificación",IF(OR(COUNT(I8:J8)<>2,I8<1,I8>5,J8<1,J8>5,MOD(I8,1)<>0,MOD(J8,1)<>0),"P e I deben ser enteros 1–5","Listo")))))))
A9: R4 | B9: A4 | C9: =IF(B9="","",IF(COUNTIF(Activos!$A$10:$A$29,B9)<>1,"ID activo inválido",IF(COUNTIFS(Activos!$A$10:$A$29,B9,Activos!$B$10:$B$29,"<>")<>1,"Falta nombre",VLOOKUP(B9,Activos!$A$10:$B$29,2,FALSE)))) | D9: T4 | E9: =IF(D9="","",IF(COUNTIF('Catálogo amenazas'!$A$5:$A$14,D9)<>1,"ID amenaza inválido",VLOOKUP(D9,'Catálogo amenazas'!$A$5:$B$14,2,FALSE))) | F9: Ausencia de respaldo eléctrico y apagado controlado | G9: D | H9: Ninguno | I9: 3 | J9: 3 | K9: P3: cortes locales 20–50% anual. I3: caída 4–8 h detiene matrícula sin pérdida de datos | L9: =IF(COUNTA(A9:B9,D9,F9:K9)=0,"",IF(A9="","Falta ID riesgo",IF(COUNTIF($A$6:$A$25,A9)<>1,"ID riesgo duplicado",IF(OR(B9="",C9="ID activo inválido",C9="Falta nombre"),"Revisar activo",IF(OR(D9="",E9="ID amenaza inválido"),"Revisar amenaza",IF(OR(F9="",G9="",H9="",K9=""),"Falta descripción o justificación",IF(OR(COUNT(I9:J9)<>2,I9<1,I9>5,J9<1,J9>5,MOD(I9,1)<>0,MOD(J9,1)<>0),"P e I deben ser enteros 1–5","Listo")))))))
A10: R5 | B10: A2 | C10: =IF(B10="","",IF(COUNTIF(Activos!$A$10:$A$29,B10)<>1,"ID activo inválido",IF(COUNTIFS(Activos!$A$10:$A$29,B10,Activos!$B$10:$B$29,"<>")<>1,"Falta nombre",VLOOKUP(B10,Activos!$A$10:$B$29,2,FALSE)))) | D10: T5 | E10: =IF(D10="","",IF(COUNTIF('Catálogo amenazas'!$A$5:$A$14,D10)<>1,"ID amenaza inválido",VLOOKUP(D10,'Catálogo amenazas'!$A$5:$B$14,2,FALSE))) | F10: Restauración de datos nunca ensayada | G10: D | H10: Ninguno | I10: 3 | J10: 4 | K10: P3: borrado por error 20–50% anual. I4: sin ensayo la recuperación supera 8 h | L10: =IF(COUNTA(A10:B10,D10,F10:K10)=0,"",IF(A10="","Falta ID riesgo",IF(COUNTIF($A$6:$A$25,A10)<>1,"ID riesgo duplicado",IF(OR(B10="",C10="ID activo inválido",C10="Falta nombre"),"Revisar activo",IF(OR(D10="",E10="ID amenaza inválido"),"Revisar amenaza",IF(OR(F10="",G10="",H10="",K10=""),"Falta descripción o justificación",IF(OR(COUNT(I10:J10)<>2,I10<1,I10>5,J10<1,J10>5,MOD(I10,1)<>0,MOD(J10,1)<>0),"P e I deben ser enteros 1–5","Listo")))))))
A11: R6 | B11: A2 | C11: =IF(B11="","",IF(COUNTIF(Activos!$A$10:$A$29,B11)<>1,"ID activo inválido",IF(COUNTIFS(Activos!$A$10:$A$29,B11,Activos!$B$10:$B$29,"<>")<>1,"Falta nombre",VLOOKUP(B11,Activos!$A$10:$B$29,2,FALSE)))) | D11: T6 | E11: =IF(D11="","",IF(COUNTIF('Catálogo amenazas'!$A$5:$A$14,D11)<>1,"ID amenaza inválido",VLOOKUP(D11,'Catálogo amenazas'!$A$5:$B$14,2,FALSE))) | F11: Archivos y enlaces compartidos sin restricción | G11: C | H11: Ninguno | I11: 3 | J11: 5 | K11: P3: enlaces abiertos, exposición 20–50%. I5: divulgación masiva de datos de estudiantes | L11: =IF(COUNTA(A11:B11,D11,F11:K11)=0,"",IF(A11="","Falta ID riesgo",IF(COUNTIF($A$6:$A$25,A11)<>1,"ID riesgo duplicado",IF(OR(B11="",C11="ID activo inválido",C11="Falta nombre"),"Revisar activo",IF(OR(D11="",E11="ID amenaza inválido"),"Revisar amenaza",IF(OR(F11="",G11="",H11="",K11=""),"Falta descripción o justificación",IF(OR(COUNT(I11:J11)<>2,I11<1,I11>5,J11<1,J11>5,MOD(I11,1)<>0,MOD(J11,1)<>0),"P e I deben ser enteros 1–5","Listo")))))))
A12: R7 | B12: A4 | C12: =IF(B12="","",IF(COUNTIF(Activos!$A$10:$A$29,B12)<>1,"ID activo inválido",IF(COUNTIFS(Activos!$A$10:$A$29,B12,Activos!$B$10:$B$29,"<>")<>1,"Falta nombre",VLOOKUP(B12,Activos!$A$10:$B$29,2,FALSE)))) | D12: T7 | E12: =IF(D12="","",IF(COUNTIF('Catálogo amenazas'!$A$5:$A$14,D12)<>1,"ID amenaza inválido",VLOOKUP(D12,'Catálogo amenazas'!$A$5:$B$14,2,FALSE))) | F12: Servidor único sin redundancia ni mantenimiento | G12: D | H12: Ninguno | I12: 2 | J12: 4 | K12: P2: falla 5–20% anual. I4: reposición 8–24 h sin repuesto | L12: =IF(COUNTA(A12:B12,D12,F12:K12)=0,"",IF(A12="","Falta ID riesgo",IF(COUNTIF($A$6:$A$25,A12)<>1,"ID riesgo duplicado",IF(OR(B12="",C12="ID activo inválido",C12="Falta nombre"),"Revisar activo",IF(OR(D12="",E12="ID amenaza inválido"),"Revisar amenaza",IF(OR(F12="",G12="",H12="",K12=""),"Falta descripción o justificación",IF(OR(COUNT(I12:J12)<>2,I12<1,I12>5,J12<1,J12>5,MOD(I12,1)<>0,MOD(J12,1)<>0),"P e I deben ser enteros 1–5","Listo")))))))
A13: R8 | B13: A1 | C13: =IF(B13="","",IF(COUNTIF(Activos!$A$10:$A$29,B13)<>1,"ID activo inválido",IF(COUNTIFS(Activos!$A$10:$A$29,B13,Activos!$B$10:$B$29,"<>")<>1,"Falta nombre",VLOOKUP(B13,Activos!$A$10:$B$29,2,FALSE)))) | D13: T8 | E13: =IF(D13="","",IF(COUNTIF('Catálogo amenazas'!$A$5:$A$14,D13)<>1,"ID amenaza inválido",VLOOKUP(D13,'Catálogo amenazas'!$A$5:$B$14,2,FALSE))) | F13: Un solo enlace sin procedimiento manual | G13: D | H13: Ninguno | I13: 2 | J13: 3 | K13: P2: corte ISP 5–20% anual. I3: matrícula detenida 4–8 h hasta registro manual | L13: =IF(COUNTA(A13:B13,D13,F13:K13)=0,"",IF(A13="","Falta ID riesgo",IF(COUNTIF($A$6:$A$25,A13)<>1,"ID riesgo duplicado",IF(OR(B13="",C13="ID activo inválido",C13="Falta nombre"),"Revisar activo",IF(OR(D13="",E13="ID amenaza inválido"),"Revisar amenaza",IF(OR(F13="",G13="",H13="",K13=""),"Falta descripción o justificación",IF(OR(COUNT(I13:J13)<>2,I13<1,I13>5,J13<1,J13>5,MOD(I13,1)<>0,MOD(J13,1)<>0),"P e I deben ser enteros 1–5","Listo")))))))
A14: R9 | B14: A2 | C14: =IF(B14="","",IF(COUNTIF(Activos!$A$10:$A$29,B14)<>1,"ID activo inválido",IF(COUNTIFS(Activos!$A$10:$A$29,B14,Activos!$B$10:$B$29,"<>")<>1,"Falta nombre",VLOOKUP(B14,Activos!$A$10:$B$29,2,FALSE)))) | D14: T9 | E14: =IF(D14="","",IF(COUNTIF('Catálogo amenazas'!$A$5:$A$14,D14)<>1,"ID amenaza inválido",VLOOKUP(D14,'Catálogo amenazas'!$A$5:$B$14,2,FALSE))) | F14: Portátil administrativo sin cifrado | G14: C | H14: Ninguno | I14: 2 | J14: 5 | K14: P2: robo 5–20% anual. I5: base de estudiantes legible implica divulgación masiva | L14: =IF(COUNTA(A14:B14,D14,F14:K14)=0,"",IF(A14="","Falta ID riesgo",IF(COUNTIF($A$6:$A$25,A14)<>1,"ID riesgo duplicado",IF(OR(B14="",C14="ID activo inválido",C14="Falta nombre"),"Revisar activo",IF(OR(D14="",E14="ID amenaza inválido"),"Revisar amenaza",IF(OR(F14="",G14="",H14="",K14=""),"Falta descripción o justificación",IF(OR(COUNT(I14:J14)<>2,I14<1,I14>5,J14<1,J14>5,MOD(I14,1)<>0,MOD(J14,1)<>0),"P e I deben ser enteros 1–5","Listo")))))))
A15: R10 | B15: A3 | C15: =IF(B15="","",IF(COUNTIF(Activos!$A$10:$A$29,B15)<>1,"ID activo inválido",IF(COUNTIFS(Activos!$A$10:$A$29,B15,Activos!$B$10:$B$29,"<>")<>1,"Falta nombre",VLOOKUP(B15,Activos!$A$10:$B$29,2,FALSE)))) | D15: T10 | E15: =IF(D15="","",IF(COUNTIF('Catálogo amenazas'!$A$5:$A$14,D15)<>1,"ID amenaza inválido",VLOOKUP(D15,'Catálogo amenazas'!$A$5:$B$14,2,FALSE))) | F15: Cambios en producción sin prueba ni reversión | G15: D | H15: Ninguno | I15: 3 | J15: 3 | K15: P3: falla 20–50% sin pruebas. I3: reversión manual degrada servicio 4–8 h | L15: =IF(COUNTA(A15:B15,D15,F15:K15)=0,"",IF(A15="","Falta ID riesgo",IF(COUNTIF($A$6:$A$25,A15)<>1,"ID riesgo duplicado",IF(OR(B15="",C15="ID activo inválido",C15="Falta nombre"),"Revisar activo",IF(OR(D15="",E15="ID amenaza inválido"),"Revisar amenaza",IF(OR(F15="",G15="",H15="",K15=""),"Falta descripción o justificación",IF(OR(COUNT(I15:J15)<>2,I15<1,I15>5,J15<1,J15>5,MOD(I15,1)<>0,MOD(J15,1)<>0),"P e I deben ser enteros 1–5","Listo")))))))
C16: =IF(B16="","",IF(COUNTIF(Activos!$A$10:$A$29,B16)<>1,"ID activo inválido",IF(COUNTIFS(Activos!$A$10:$A$29,B16,Activos!$B$10:$B$29,"<>")<>1,"Falta nombre",VLOOKUP(B16,Activos!$A$10:$B$29,2,FALSE)))) | E16: =IF(D16="","",IF(COUNTIF('Catálogo amenazas'!$A$5:$A$14,D16)<>1,"ID amenaza inválido",VLOOKUP(D16,'Catálogo amenazas'!$A$5:$B$14,2,FALSE))) | L16: =IF(COUNTA(A16:B16,D16,F16:K16)=0,"",IF(A16="","Falta ID riesgo",IF(COUNTIF($A$6:$A$25,A16)<>1,"ID riesgo duplicado",IF(OR(B16="",C16="ID activo inválido",C16="Falta nombre"),"Revisar activo",IF(OR(D16="",E16="ID amenaza inválido"),"Revisar amenaza",IF(OR(F16="",G16="",H16="",K16=""),"Falta descripción o justificación",IF(OR(COUNT(I16:J16)<>2,I16<1,I16>5,J16<1,J16>5,MOD(I16,1)<>0,MOD(J16,1)<>0),"P e I deben ser enteros 1–5","Listo")))))))
C17: =IF(B17="","",IF(COUNTIF(Activos!$A$10:$A$29,B17)<>1,"ID activo inválido",IF(COUNTIFS(Activos!$A$10:$A$29,B17,Activos!$B$10:$B$29,"<>")<>1,"Falta nombre",VLOOKUP(B17,Activos!$A$10:$B$29,2,FALSE)))) | E17: =IF(D17="","",IF(COUNTIF('Catálogo amenazas'!$A$5:$A$14,D17)<>1,"ID amenaza inválido",VLOOKUP(D17,'Catálogo amenazas'!$A$5:$B$14,2,FALSE))) | L17: =IF(COUNTA(A17:B17,D17,F17:K17)=0,"",IF(A17="","Falta ID riesgo",IF(COUNTIF($A$6:$A$25,A17)<>1,"ID riesgo duplicado",IF(OR(B17="",C17="ID activo inválido",C17="Falta nombre"),"Revisar activo",IF(OR(D17="",E17="ID amenaza inválido"),"Revisar amenaza",IF(OR(F17="",G17="",H17="",K17=""),"Falta descripción o justificación",IF(OR(COUNT(I17:J17)<>2,I17<1,I17>5,J17<1,J17>5,MOD(I17,1)<>0,MOD(J17,1)<>0),"P e I deben ser enteros 1–5","Listo")))))))
C18: =IF(B18="","",IF(COUNTIF(Activos!$A$10:$A$29,B18)<>1,"ID activo inválido",IF(COUNTIFS(Activos!$A$10:$A$29,B18,Activos!$B$10:$B$29,"<>")<>1,"Falta nombre",VLOOKUP(B18,Activos!$A$10:$B$29,2,FALSE)))) | E18: =IF(D18="","",IF(COUNTIF('Catálogo amenazas'!$A$5:$A$14,D18)<>1,"ID amenaza inválido",VLOOKUP(D18,'Catálogo amenazas'!$A$5:$B$14,2,FALSE))) | L18: =IF(COUNTA(A18:B18,D18,F18:K18)=0,"",IF(A18="","Falta ID riesgo",IF(COUNTIF($A$6:$A$25,A18)<>1,"ID riesgo duplicado",IF(OR(B18="",C18="ID activo inválido",C18="Falta nombre"),"Revisar activo",IF(OR(D18="",E18="ID amenaza inválido"),"Revisar amenaza",IF(OR(F18="",G18="",H18="",K18=""),"Falta descripción o justificación",IF(OR(COUNT(I18:J18)<>2,I18<1,I18>5,J18<1,J18>5,MOD(I18,1)<>0,MOD(J18,1)<>0),"P e I deben ser enteros 1–5","Listo")))))))
C19: =IF(B19="","",IF(COUNTIF(Activos!$A$10:$A$29,B19)<>1,"ID activo inválido",IF(COUNTIFS(Activos!$A$10:$A$29,B19,Activos!$B$10:$B$29,"<>")<>1,"Falta nombre",VLOOKUP(B19,Activos!$A$10:$B$29,2,FALSE)))) | E19: =IF(D19="","",IF(COUNTIF('Catálogo amenazas'!$A$5:$A$14,D19)<>1,"ID amenaza inválido",VLOOKUP(D19,'Catálogo amenazas'!$A$5:$B$14,2,FALSE))) | L19: =IF(COUNTA(A19:B19,D19,F19:K19)=0,"",IF(A19="","Falta ID riesgo",IF(COUNTIF($A$6:$A$25,A19)<>1,"ID riesgo duplicado",IF(OR(B19="",C19="ID activo inválido",C19="Falta nombre"),"Revisar activo",IF(OR(D19="",E19="ID amenaza inválido"),"Revisar amenaza",IF(OR(F19="",G19="",H19="",K19=""),"Falta descripción o justificación",IF(OR(COUNT(I19:J19)<>2,I19<1,I19>5,J19<1,J19>5,MOD(I19,1)<>0,MOD(J19,1)<>0),"P e I deben ser enteros 1–5","Listo")))))))
C20: =IF(B20="","",IF(COUNTIF(Activos!$A$10:$A$29,B20)<>1,"ID activo inválido",IF(COUNTIFS(Activos!$A$10:$A$29,B20,Activos!$B$10:$B$29,"<>")<>1,"Falta nombre",VLOOKUP(B20,Activos!$A$10:$B$29,2,FALSE)))) | E20: =IF(D20="","",IF(COUNTIF('Catálogo amenazas'!$A$5:$A$14,D20)<>1,"ID amenaza inválido",VLOOKUP(D20,'Catálogo amenazas'!$A$5:$B$14,2,FALSE))) | L20: =IF(COUNTA(A20:B20,D20,F20:K20)=0,"",IF(A20="","Falta ID riesgo",IF(COUNTIF($A$6:$A$25,A20)<>1,"ID riesgo duplicado",IF(OR(B20="",C20="ID activo inválido",C20="Falta nombre"),"Revisar activo",IF(OR(D20="",E20="ID amenaza inválido"),"Revisar amenaza",IF(OR(F20="",G20="",H20="",K20=""),"Falta descripción o justificación",IF(OR(COUNT(I20:J20)<>2,I20<1,I20>5,J20<1,J20>5,MOD(I20,1)<>0,MOD(J20,1)<>0),"P e I deben ser enteros 1–5","Listo")))))))
C21: =IF(B21="","",IF(COUNTIF(Activos!$A$10:$A$29,B21)<>1,"ID activo inválido",IF(COUNTIFS(Activos!$A$10:$A$29,B21,Activos!$B$10:$B$29,"<>")<>1,"Falta nombre",VLOOKUP(B21,Activos!$A$10:$B$29,2,FALSE)))) | E21: =IF(D21="","",IF(COUNTIF('Catálogo amenazas'!$A$5:$A$14,D21)<>1,"ID amenaza inválido",VLOOKUP(D21,'Catálogo amenazas'!$A$5:$B$14,2,FALSE))) | L21: =IF(COUNTA(A21:B21,D21,F21:K21)=0,"",IF(A21="","Falta ID riesgo",IF(COUNTIF($A$6:$A$25,A21)<>1,"ID riesgo duplicado",IF(OR(B21="",C21="ID activo inválido",C21="Falta nombre"),"Revisar activo",IF(OR(D21="",E21="ID amenaza inválido"),"Revisar amenaza",IF(OR(F21="",G21="",H21="",K21=""),"Falta descripción o justificación",IF(OR(COUNT(I21:J21)<>2,I21<1,I21>5,J21<1,J21>5,MOD(I21,1)<>0,MOD(J21,1)<>0),"P e I deben ser enteros 1–5","Listo")))))))
C22: =IF(B22="","",IF(COUNTIF(Activos!$A$10:$A$29,B22)<>1,"ID activo inválido",IF(COUNTIFS(Activos!$A$10:$A$29,B22,Activos!$B$10:$B$29,"<>")<>1,"Falta nombre",VLOOKUP(B22,Activos!$A$10:$B$29,2,FALSE)))) | E22: =IF(D22="","",IF(COUNTIF('Catálogo amenazas'!$A$5:$A$14,D22)<>1,"ID amenaza inválido",VLOOKUP(D22,'Catálogo amenazas'!$A$5:$B$14,2,FALSE))) | L22: =IF(COUNTA(A22:B22,D22,F22:K22)=0,"",IF(A22="","Falta ID riesgo",IF(COUNTIF($A$6:$A$25,A22)<>1,"ID riesgo duplicado",IF(OR(B22="",C22="ID activo inválido",C22="Falta nombre"),"Revisar activo",IF(OR(D22="",E22="ID amenaza inválido"),"Revisar amenaza",IF(OR(F22="",G22="",H22="",K22=""),"Falta descripción o justificación",IF(OR(COUNT(I22:J22)<>2,I22<1,I22>5,J22<1,J22>5,MOD(I22,1)<>0,MOD(J22,1)<>0),"P e I deben ser enteros 1–5","Listo")))))))
C23: =IF(B23="","",IF(COUNTIF(Activos!$A$10:$A$29,B23)<>1,"ID activo inválido",IF(COUNTIFS(Activos!$A$10:$A$29,B23,Activos!$B$10:$B$29,"<>")<>1,"Falta nombre",VLOOKUP(B23,Activos!$A$10:$B$29,2,FALSE)))) | E23: =IF(D23="","",IF(COUNTIF('Catálogo amenazas'!$A$5:$A$14,D23)<>1,"ID amenaza inválido",VLOOKUP(D23,'Catálogo amenazas'!$A$5:$B$14,2,FALSE))) | L23: =IF(COUNTA(A23:B23,D23,F23:K23)=0,"",IF(A23="","Falta ID riesgo",IF(COUNTIF($A$6:$A$25,A23)<>1,"ID riesgo duplicado",IF(OR(B23="",C23="ID activo inválido",C23="Falta nombre"),"Revisar activo",IF(OR(D23="",E23="ID amenaza inválido"),"Revisar amenaza",IF(OR(F23="",G23="",H23="",K23=""),"Falta descripción o justificación",IF(OR(COUNT(I23:J23)<>2,I23<1,I23>5,J23<1,J23>5,MOD(I23,1)<>0,MOD(J23,1)<>0),"P e I deben ser enteros 1–5","Listo")))))))
C24: =IF(B24="","",IF(COUNTIF(Activos!$A$10:$A$29,B24)<>1,"ID activo inválido",IF(COUNTIFS(Activos!$A$10:$A$29,B24,Activos!$B$10:$B$29,"<>")<>1,"Falta nombre",VLOOKUP(B24,Activos!$A$10:$B$29,2,FALSE)))) | E24: =IF(D24="","",IF(COUNTIF('Catálogo amenazas'!$A$5:$A$14,D24)<>1,"ID amenaza inválido",VLOOKUP(D24,'Catálogo amenazas'!$A$5:$B$14,2,FALSE))) | L24: =IF(COUNTA(A24:B24,D24,F24:K24)=0,"",IF(A24="","Falta ID riesgo",IF(COUNTIF($A$6:$A$25,A24)<>1,"ID riesgo duplicado",IF(OR(B24="",C24="ID activo inválido",C24="Falta nombre"),"Revisar activo",IF(OR(D24="",E24="ID amenaza inválido"),"Revisar amenaza",IF(OR(F24="",G24="",H24="",K24=""),"Falta descripción o justificación",IF(OR(COUNT(I24:J24)<>2,I24<1,I24>5,J24<1,J24>5,MOD(I24,1)<>0,MOD(J24,1)<>0),"P e I deben ser enteros 1–5","Listo")))))))
C25: =IF(B25="","",IF(COUNTIF(Activos!$A$10:$A$29,B25)<>1,"ID activo inválido",IF(COUNTIFS(Activos!$A$10:$A$29,B25,Activos!$B$10:$B$29,"<>")<>1,"Falta nombre",VLOOKUP(B25,Activos!$A$10:$B$29,2,FALSE)))) | E25: =IF(D25="","",IF(COUNTIF('Catálogo amenazas'!$A$5:$A$14,D25)<>1,"ID amenaza inválido",VLOOKUP(D25,'Catálogo amenazas'!$A$5:$B$14,2,FALSE))) | L25: =IF(COUNTA(A25:B25,D25,F25:K25)=0,"",IF(A25="","Falta ID riesgo",IF(COUNTIF($A$6:$A$25,A25)<>1,"ID riesgo duplicado",IF(OR(B25="",C25="ID activo inválido",C25="Falta nombre"),"Revisar activo",IF(OR(D25="",E25="ID amenaza inválido"),"Revisar amenaza",IF(OR(F25="",G25="",H25="",K25=""),"Falta descripción o justificación",IF(OR(COUNT(I25:J25)<>2,I25<1,I25>5,J25<1,J25>5,MOD(I25,1)<>0,MOD(J25,1)<>0),"P e I deben ser enteros 1–5","Listo")))))))

Sheet Análisis de Riesgos
A2: Resultados y plan de tratamiento del alumno
A3: Resultados actualizados desde Cruces. Residual previsto hasta comprobar el control. Complete decisiones y evidencias.
A5: ID | B5: Activo | C5: Amenaza | D5: P | E5: I | F5: R actual | G5: Nivel | H5: Atención | I5: Estado fuente
A6: =IF('Cruces Activo-Amenaza'!A6="","",'Cruces Activo-Amenaza'!A6) | B6: =IF('Cruces Activo-Amenaza'!C6="","",'Cruces Activo-Amenaza'!C6) | C6: =IF('Cruces Activo-Amenaza'!E6="","",'Cruces Activo-Amenaza'!E6) | D6: =IF('Cruces Activo-Amenaza'!L6="Listo",'Cruces Activo-Amenaza'!I6,"") | E6: =IF('Cruces Activo-Amenaza'!L6="Listo",'Cruces Activo-Amenaza'!J6,"") | F6: =IF(I6="Listo",D6*E6,"") | G6: =IF(F6="","",IF(F6<'Tablas AR'!$A$17,"Bajo",IF(F6<'Tablas AR'!$A$18,"Moderado",IF(F6<'Tablas AR'!$A$19,"Alto","Crítico")))) | H6: =IF(F6="","",IF(F6>='Tablas AR'!$A$19,"Urgente",IF(F6>='Tablas AR'!$A$18,"Prioritaria",IF(F6>='Tablas AR'!$A$17,"Programar","Evaluar aceptación")))) | I6: =IF('Cruces Activo-Amenaza'!L6="","",'Cruces Activo-Amenaza'!L6)
A7: =IF('Cruces Activo-Amenaza'!A7="","",'Cruces Activo-Amenaza'!A7) | B7: =IF('Cruces Activo-Amenaza'!C7="","",'Cruces Activo-Amenaza'!C7) | C7: =IF('Cruces Activo-Amenaza'!E7="","",'Cruces Activo-Amenaza'!E7) | D7: =IF('Cruces Activo-Amenaza'!L7="Listo",'Cruces Activo-Amenaza'!I7,"") | E7: =IF('Cruces Activo-Amenaza'!L7="Listo",'Cruces Activo-Amenaza'!J7,"") | F7: =IF(I7="Listo",D7*E7,"") | G7: =IF(F7="","",IF(F7<'Tablas AR'!$A$17,"Bajo",IF(F7<'Tablas AR'!$A$18,"Moderado",IF(F7<'Tablas AR'!$A$19,"Alto","Crítico")))) | H7: =IF(F7="","",IF(F7>='Tablas AR'!$A$19,"Urgente",IF(F7>='Tablas AR'!$A$18,"Prioritaria",IF(F7>='Tablas AR'!$A$17,"Programar","Evaluar aceptación")))) | I7: =IF('Cruces Activo-Amenaza'!L7="","",'Cruces Activo-Amenaza'!L7)
A8: =IF('Cruces Activo-Amenaza'!A8="","",'Cruces Activo-Amenaza'!A8) | B8: =IF('Cruces Activo-Amenaza'!C8="","",'Cruces Activo-Amenaza'!C8) | C8: =IF('Cruces Activo-Amenaza'!E8="","",'Cruces Activo-Amenaza'!E8) | D8: =IF('Cruces Activo-Amenaza'!L8="Listo",'Cruces Activo-Amenaza'!I8,"") | E8: =IF('Cruces Activo-Amenaza'!L8="Listo",'Cruces Activo-Amenaza'!J8,"") | F8: =IF(I8="Listo",D8*E8,"") | G8: =IF(F8="","",IF(F8<'Tablas AR'!$A$17,"Bajo",IF(F8<'Tablas AR'!$A$18,"Moderado",IF(F8<'Tablas AR'!$A$19,"Alto","Crítico")))) | H8: =IF(F8="","",IF(F8>='Tablas AR'!$A$19,"Urgente",IF(F8>='Tablas AR'!$A$18,"Prioritaria",IF(F8>='Tablas AR'!$A$17,"Programar","Evaluar aceptación")))) | I8: =IF('Cruces Activo-Amenaza'!L8="","",'Cruces Activo-Amenaza'!L8)
A9: =IF('Cruces Activo-Amenaza'!A9="","",'Cruces Activo-Amenaza'!A9) | B9: =IF('Cruces Activo-Amenaza'!C9="","",'Cruces Activo-Amenaza'!C9) | C9: =IF('Cruces Activo-Amenaza'!E9="","",'Cruces Activo-Amenaza'!E9) | D9: =IF('Cruces Activo-Amenaza'!L9="Listo",'Cruces Activo-Amenaza'!I9,"") | E9: =IF('Cruces Activo-Amenaza'!L9="Listo",'Cruces Activo-Amenaza'!J9,"") | F9: =IF(I9="Listo",D9*E9,"") | G9: =IF(F9="","",IF(F9<'Tablas AR'!$A$17,"Bajo",IF(F9<'Tablas AR'!$A$18,"Moderado",IF(F9<'Tablas AR'!$A$19,"Alto","Crítico")))) | H9: =IF(F9="","",IF(F9>='Tablas AR'!$A$19,"Urgente",IF(F9>='Tablas AR'!$A$18,"Prioritaria",IF(F9>='Tablas AR'!$A$17,"Programar","Evaluar aceptación")))) | I9: =IF('Cruces Activo-Amenaza'!L9="","",'Cruces Activo-Amenaza'!L9)
A10: =IF('Cruces Activo-Amenaza'!A10="","",'Cruces Activo-Amenaza'!A10) | B10: =IF('Cruces Activo-Amenaza'!C10="","",'Cruces Activo-Amenaza'!C10) | C10: =IF('Cruces Activo-Amenaza'!E10="","",'Cruces Activo-Amenaza'!E10) | D10: =IF('Cruces Activo-Amenaza'!L10="Listo",'Cruces Activo-Amenaza'!I10,"") | E10: =IF('Cruces Activo-Amenaza'!L10="Listo",'Cruces Activo-Amenaza'!J10,"") | F10: =IF(I10="Listo",D10*E10,"") | G10: =IF(F10="","",IF(F10<'Tablas AR'!$A$17,"Bajo",IF(F10<'Tablas AR'!$A$18,"Moderado",IF(F10<'Tablas AR'!$A$19,"Alto","Crítico")))) | H10: =IF(F10="","",IF(F10>='Tablas AR'!$A$19,"Urgente",IF(F10>='Tablas AR'!$A$18,"Prioritaria",IF(F10>='Tablas AR'!$A$17,"Programar","Evaluar aceptación")))) | I10: =IF('Cruces Activo-Amenaza'!L10="","",'Cruces Activo-Amenaza'!L10)
A11: =IF('Cruces Activo-Amenaza'!A11="","",'Cruces Activo-Amenaza'!A11) | B11: =IF('Cruces Activo-Amenaza'!C11="","",'Cruces Activo-Amenaza'!C11) | C11: =IF('Cruces Activo-Amenaza'!E11="","",'Cruces Activo-Amenaza'!E11) | D11: =IF('Cruces Activo-Amenaza'!L11="Listo",'Cruces Activo-Amenaza'!I11,"") | E11: =IF('Cruces Activo-Amenaza'!L11="Listo",'Cruces Activo-Amenaza'!J11,"") | F11: =IF(I11="Listo",D11*E11,"") | G11: =IF(F11="","",IF(F11<'Tablas AR'!$A$17,"Bajo",IF(F11<'Tablas AR'!$A$18,"Moderado",IF(F11<'Tablas AR'!$A$19,"Alto","Crítico")))) | H11: =IF(F11="","",IF(F11>='Tablas AR'!$A$19,"Urgente",IF(F11>='Tablas AR'!$A$18,"Prioritaria",IF(F11>='Tablas AR'!$A$17,"Programar","Evaluar aceptación")))) | I11: =IF('Cruces Activo-Amenaza'!L11="","",'Cruces Activo-Amenaza'!L11)
A12: =IF('Cruces Activo-Amenaza'!A12="","",'Cruces Activo-Amenaza'!A12) | B12: =IF('Cruces Activo-Amenaza'!C12="","",'Cruces Activo-Amenaza'!C12) | C12: =IF('Cruces Activo-Amenaza'!E12="","",'Cruces Activo-Amenaza'!E12) | D12: =IF('Cruces Activo-Amenaza'!L12="Listo",'Cruces Activo-Amenaza'!I12,"") | E12: =IF('Cruces Activo-Amenaza'!L12="Listo",'Cruces Activo-Amenaza'!J12,"") | F12: =IF(I12="Listo",D12*E12,"") | G12: =IF(F12="","",IF(F12<'Tablas AR'!$A$17,"Bajo",IF(F12<'Tablas AR'!$A$18,"Moderado",IF(F12<'Tablas AR'!$A$19,"Alto","Crítico")))) | H12: =IF(F12="","",IF(F12>='Tablas AR'!$A$19,"Urgente",IF(F12>='Tablas AR'!$A$18,"Prioritaria",IF(F12>='Tablas AR'!$A$17,"Programar","Evaluar aceptación")))) | I12: =IF('Cruces Activo-Amenaza'!L12="","",'Cruces Activo-Amenaza'!L12)
A13: =IF('Cruces Activo-Amenaza'!A13="","",'Cruces Activo-Amenaza'!A13) | B13: =IF('Cruces Activo-Amenaza'!C13="","",'Cruces Activo-Amenaza'!C13) | C13: =IF('Cruces Activo-Amenaza'!E13="","",'Cruces Activo-Amenaza'!E13) | D13: =IF('Cruces Activo-Amenaza'!L13="Listo",'Cruces Activo-Amenaza'!I13,"") | E13: =IF('Cruces Activo-Amenaza'!L13="Listo",'Cruces Activo-Amenaza'!J13,"") | F13: =IF(I13="Listo",D13*E13,"") | G13: =IF(F13="","",IF(F13<'Tablas AR'!$A$17,"Bajo",IF(F13<'Tablas AR'!$A$18,"Moderado",IF(F13<'Tablas AR'!$A$19,"Alto","Crítico")))) | H13: =IF(F13="","",IF(F13>='Tablas AR'!$A$19,"Urgente",IF(F13>='Tablas AR'!$A$18,"Prioritaria",IF(F13>='Tablas AR'!$A$17,"Programar","Evaluar aceptación")))) | I13: =IF('Cruces Activo-Amenaza'!L13="","",'Cruces Activo-Amenaza'!L13)
A14: =IF('Cruces Activo-Amenaza'!A14="","",'Cruces Activo-Amenaza'!A14) | B14: =IF('Cruces Activo-Amenaza'!C14="","",'Cruces Activo-Amenaza'!C14) | C14: =IF('Cruces Activo-Amenaza'!E14="","",'Cruces Activo-Amenaza'!E14) | D14: =IF('Cruces Activo-Amenaza'!L14="Listo",'Cruces Activo-Amenaza'!I14,"") | E14: =IF('Cruces Activo-Amenaza'!L14="Listo",'Cruces Activo-Amenaza'!J14,"") | F14: =IF(I14="Listo",D14*E14,"") | G14: =IF(F14="","",IF(F14<'Tablas AR'!$A$17,"Bajo",IF(F14<'Tablas AR'!$A$18,"Moderado",IF(F14<'Tablas AR'!$A$19,"Alto","Crítico")))) | H14: =IF(F14="","",IF(F14>='Tablas AR'!$A$19,"Urgente",IF(F14>='Tablas AR'!$A$18,"Prioritaria",IF(F14>='Tablas AR'!$A$17,"Programar","Evaluar aceptación")))) | I14: =IF('Cruces Activo-Amenaza'!L14="","",'Cruces Activo-Amenaza'!L14)
A15: =IF('Cruces Activo-Amenaza'!A15="","",'Cruces Activo-Amenaza'!A15) | B15: =IF('Cruces Activo-Amenaza'!C15="","",'Cruces Activo-Amenaza'!C15) | C15: =IF('Cruces Activo-Amenaza'!E15="","",'Cruces Activo-Amenaza'!E15) | D15: =IF('Cruces Activo-Amenaza'!L15="Listo",'Cruces Activo-Amenaza'!I15,"") | E15: =IF('Cruces Activo-Amenaza'!L15="Listo",'Cruces Activo-Amenaza'!J15,"") | F15: =IF(I15="Listo",D15*E15,"") | G15: =IF(F15="","",IF(F15<'Tablas AR'!$A$17,"Bajo",IF(F15<'Tablas AR'!$A$18,"Moderado",IF(F15<'Tablas AR'!$A$19,"Alto","Crítico")))) | H15: =IF(F15="","",IF(F15>='Tablas AR'!$A$19,"Urgente",IF(F15>='Tablas AR'!$A$18,"Prioritaria",IF(F15>='Tablas AR'!$A$17,"Programar","Evaluar aceptación")))) | I15: =IF('Cruces Activo-Amenaza'!L15="","",'Cruces Activo-Amenaza'!L15)
A16: =IF('Cruces Activo-Amenaza'!A16="","",'Cruces Activo-Amenaza'!A16) | B16: =IF('Cruces Activo-Amenaza'!C16="","",'Cruces Activo-Amenaza'!C16) | C16: =IF('Cruces Activo-Amenaza'!E16="","",'Cruces Activo-Amenaza'!E16) | D16: =IF('Cruces Activo-Amenaza'!L16="Listo",'Cruces Activo-Amenaza'!I16,"") | E16: =IF('Cruces Activo-Amenaza'!L16="Listo",'Cruces Activo-Amenaza'!J16,"") | F16: =IF(I16="Listo",D16*E16,"") | G16: =IF(F16="","",IF(F16<'Tablas AR'!$A$17,"Bajo",IF(F16<'Tablas AR'!$A$18,"Moderado",IF(F16<'Tablas AR'!$A$19,"Alto","Crítico")))) | H16: =IF(F16="","",IF(F16>='Tablas AR'!$A$19,"Urgente",IF(F16>='Tablas AR'!$A$18,"Prioritaria",IF(F16>='Tablas AR'!$A$17,"Programar","Evaluar aceptación")))) | I16: =IF('Cruces Activo-Amenaza'!L16="","",'Cruces Activo-Amenaza'!L16)
A17: =IF('Cruces Activo-Amenaza'!A17="","",'Cruces Activo-Amenaza'!A17) | B17: =IF('Cruces Activo-Amenaza'!C17="","",'Cruces Activo-Amenaza'!C17) | C17: =IF('Cruces Activo-Amenaza'!E17="","",'Cruces Activo-Amenaza'!E17) | D17: =IF('Cruces Activo-Amenaza'!L17="Listo",'Cruces Activo-Amenaza'!I17,"") | E17: =IF('Cruces Activo-Amenaza'!L17="Listo",'Cruces Activo-Amenaza'!J17,"") | F17: =IF(I17="Listo",D17*E17,"") | G17: =IF(F17="","",IF(F17<'Tablas AR'!$A$17,"Bajo",IF(F17<'Tablas AR'!$A$18,"Moderado",IF(F17<'Tablas AR'!$A$19,"Alto","Crítico")))) | H17: =IF(F17="","",IF(F17>='Tablas AR'!$A$19,"Urgente",IF(F17>='Tablas AR'!$A$18,"Prioritaria",IF(F17>='Tablas AR'!$A$17,"Programar","Evaluar aceptación")))) | I17: =IF('Cruces Activo-Amenaza'!L17="","",'Cruces Activo-Amenaza'!L17)
... A25: =IF('Cruces Activo-Amenaza'!A25="","",'Cruces Activo-Amenaza'!A25) | B25: =IF('Cruces Activo-Amenaza'!C25="","",'Cruces Activo-Amenaza'!C25) | C25: =IF('Cruces Activo-Amenaza'!E25="","",'Cruces Activo-Amenaza'!E25) | D25: =IF('Cruces Activo-Amenaza'!L25="Listo",'Cruces Activo-Amenaza'!I25,"") | E25: =IF('Cruces Activo-Amenaza'!L25="Listo",'Cruces Activo-Amenaza'!J25,"") | F25: =IF(I25="Listo",D25*E25,"") | G25: =IF(F25="","",IF(F25<'Tablas AR'!$A$17,"Bajo",IF(F25<'Tablas AR'!$A$18,"Moderado",IF(F25<'Tablas AR'!$A$19,"Alto","Crítico")))) | H25: =IF(F25="","",IF(F25>='Tablas AR'!$A$19,"Urgente",IF(F25>='Tablas AR'!$A$18,"Prioritaria",IF(F25>='Tablas AR'!$A$17,"Programar","Evaluar aceptación")))) | I25: =IF('Cruces Activo-Amenaza'!L25="","",'Cruces Activo-Amenaza'!L25)
A30: ID | B30: Tratamiento | C30: Acción concreta | D30: Responsable | E30: Plazo días | F30: Estado control | G30: Evidencia o supuesto | H30: P resid. | I30: I resid. | J30: R resid. | K30: Nivel residual | L30: Reducción índice | M30: Condición del residual | N30: Decisión responsable
A31: =IF(A6="","",A6) | B31: Mitigar | C31: Copias aisladas 3-2-1 y ensayo trimestral de restauración | D31: Administrador TI | E31: 30 | F31: Propuesto | G31: Supuesto didáctico: disco externo y rutina de copia aislada | H31: 1 | I31: 3 | J31: =IF(A31="","",IF(I6<>"Listo","Falta evaluación actual",IF(OR(COUNT(H31:I31)<>2,H31<1,H31>5,I31<1,I31>5,MOD(H31,1)<>0,MOD(I31,1)<>0),"Faltan P/I válidos",H31*I31))) | K31: =IF(ISNUMBER(J31),IF(J31<'Tablas AR'!$A$17,"Bajo",IF(J31<'Tablas AR'!$A$18,"Moderado",IF(J31<'Tablas AR'!$A$19,"Alto","Crítico"))),"") | L31: =IF(ISNUMBER(J31),(F6-J31)/F6,"") | M31: =IF(A31="","",IF(OR(B31="",C31="",D31="",NOT(ISNUMBER(E31)),E31<=0,F31="",G31="",N31=""),"Completar tratamiento y decisión",IF(NOT(ISNUMBER(J31)),"Completar evaluación",IF(F31="Verificado",IF(J31<='Tablas AR'!$B$22,"Verificado; revisar aceptación","Verificado; requiere tratamiento"),IF(J31<='Tablas AR'!$B$22,"Previsto; requiere prueba","Previsto; requiere tratamiento"))))) | N31: Solicitar aceptación
A32: =IF(A7="","",A7) | B32: Mitigar | C32: Segundo factor en cuentas y entrenamiento anti-phishing | D32: Administración del Sistema | E32: 30 | F32: Propuesto | G32: Supuesto didáctico: app TOTP gratuita y charla de 2 h | H32: 2 | I32: 2 | J32: =IF(A32="","",IF(I7<>"Listo","Falta evaluación actual",IF(OR(COUNT(H32:I32)<>2,H32<1,H32>5,I32<1,I32>5,MOD(H32,1)<>0,MOD(I32,1)<>0),"Faltan P/I válidos",H32*I32))) | K32: =IF(ISNUMBER(J32),IF(J32<'Tablas AR'!$A$17,"Bajo",IF(J32<'Tablas AR'!$A$18,"Moderado",IF(J32<'Tablas AR'!$A$19,"Alto","Crítico"))),"") | L32: =IF(ISNUMBER(J32),(F7-J32)/F7,"") | M32: =IF(A32="","",IF(OR(B32="",C32="",D32="",NOT(ISNUMBER(E32)),E32<=0,F32="",G32="",N32=""),"Completar tratamiento y decisión",IF(NOT(ISNUMBER(J32)),"Completar evaluación",IF(F32="Verificado",IF(J32<='Tablas AR'!$B$22,"Verificado; revisar aceptación","Verificado; requiere tratamiento"),IF(J32<='Tablas AR'!$B$22,"Previsto; requiere prueba","Previsto; requiere tratamiento"))))) | N32: Solicitar aceptación
A33: =IF(A8="","",A8) | B33: Mitigar | C33: Permisos por rol, aprobación de cambios de notas y bitácora | D33: Administración del Sistema | E33: 20 | F33: Propuesto | G33: Supuesto didáctico: roles y auditoría (FR-20) | H33: 1 | I33: 4 | J33: =IF(A33="","",IF(I8<>"Listo","Falta evaluación actual",IF(OR(COUNT(H33:I33)<>2,H33<1,H33>5,I33<1,I33>5,MOD(H33,1)<>0,MOD(I33,1)<>0),"Faltan P/I válidos",H33*I33))) | K33: =IF(ISNUMBER(J33),IF(J33<'Tablas AR'!$A$17,"Bajo",IF(J33<'Tablas AR'!$A$18,"Moderado",IF(J33<'Tablas AR'!$A$19,"Alto","Crítico"))),"") | L33: =IF(ISNUMBER(J33),(F8-J33)/F8,"") | M33: =IF(A33="","",IF(OR(B33="",C33="",D33="",NOT(ISNUMBER(E33)),E33<=0,F33="",G33="",N33=""),"Completar tratamiento y decisión",IF(NOT(ISNUMBER(J33)),"Completar evaluación",IF(F33="Verificado",IF(J33<='Tablas AR'!$B$22,"Verificado; revisar aceptación","Verificado; requiere tratamiento"),IF(J33<='Tablas AR'!$B$22,"Previsto; requiere prueba","Previsto; requiere tratamiento"))))) | N33: Solicitar aceptación
A34: =IF(A9="","",A9) | B34: Mitigar | C34: UPS y procedimiento de apagado controlado | D34: Infraestructura TI | E34: 30 | F34: Propuesto | G34: Supuesto didáctico: UPS cotizado, pendiente de compra | H34: 2 | I34: 2 | J34: =IF(A34="","",IF(I9<>"Listo","Falta evaluación actual",IF(OR(COUNT(H34:I34)<>2,H34<1,H34>5,I34<1,I34>5,MOD(H34,1)<>0,MOD(I34,1)<>0),"Faltan P/I válidos",H34*I34))) | K34: =IF(ISNUMBER(J34),IF(J34<'Tablas AR'!$A$17,"Bajo",IF(J34<'Tablas AR'!$A$18,"Moderado",IF(J34<'Tablas AR'!$A$19,"Alto","Crítico"))),"") | L34: =IF(ISNUMBER(J34),(F9-J34)/F9,"") | M34: =IF(A34="","",IF(OR(B34="",C34="",D34="",NOT(ISNUMBER(E34)),E34<=0,F34="",G34="",N34=""),"Completar tratamiento y decisión",IF(NOT(ISNUMBER(J34)),"Completar evaluación",IF(F34="Verificado",IF(J34<='Tablas AR'!$B$22,"Verificado; revisar aceptación","Verificado; requiere tratamiento"),IF(J34<='Tablas AR'!$B$22,"Previsto; requiere prueba","Previsto; requiere tratamiento"))))) | N34: Solicitar aceptación
A35: =IF(A10="","",A10) | B35: Mitigar | C35: Versionado de base de datos y prueba semestral de restauración | D35: Administrador TI | E35: 15 | F35: Propuesto | G35: Supuesto didáctico: ensayo documentado con acta | H35: 2 | I35: 2 | J35: =IF(A35="","",IF(I10<>"Listo","Falta evaluación actual",IF(OR(COUNT(H35:I35)<>2,H35<1,H35>5,I35<1,I35>5,MOD(H35,1)<>0,MOD(I35,1)<>0),"Faltan P/I válidos",H35*I35))) | K35: =IF(ISNUMBER(J35),IF(J35<'Tablas AR'!$A$17,"Bajo",IF(J35<'Tablas AR'!$A$18,"Moderado",IF(J35<'Tablas AR'!$A$19,"Alto","Crítico"))),"") | L35: =IF(ISNUMBER(J35),(F10-J35)/F10,"") | M35: =IF(A35="","",IF(OR(B35="",C35="",D35="",NOT(ISNUMBER(E35)),E35<=0,F35="",G35="",N35=""),"Completar tratamiento y decisión",IF(NOT(ISNUMBER(J35)),"Completar evaluación",IF(F35="Verificado",IF(J35<='Tablas AR'!$B$22,"Verificado; revisar aceptación","Verificado; requiere tratamiento"),IF(J35<='Tablas AR'!$B$22,"Previsto; requiere prueba","Previsto; requiere tratamiento"))))) | N35: Solicitar aceptación
A36: =IF(A11="","",A11) | B36: Mitigar | C36: Acceso mínimo, bloqueo de enlaces públicos y revisión mensual | D36: Secretaría Académica | E36: 15 | F36: Propuesto | G36: Supuesto didáctico: primera fase; fase 2 con DLP pendiente | H36: 1 | I36: 5 | J36: =IF(A36="","",IF(I11<>"Listo","Falta evaluación actual",IF(OR(COUNT(H36:I36)<>2,H36<1,H36>5,I36<1,I36>5,MOD(H36,1)<>0,MOD(I36,1)<>0),"Faltan P/I válidos",H36*I36))) | K36: =IF(ISNUMBER(J36),IF(J36<'Tablas AR'!$A$17,"Bajo",IF(J36<'Tablas AR'!$A$18,"Moderado",IF(J36<'Tablas AR'!$A$19,"Alto","Crítico"))),"") | L36: =IF(ISNUMBER(J36),(F11-J36)/F11,"") | M36: =IF(A36="","",IF(OR(B36="",C36="",D36="",NOT(ISNUMBER(E36)),E36<=0,F36="",G36="",N36=""),"Completar tratamiento y decisión",IF(NOT(ISNUMBER(J36)),"Completar evaluación",IF(F36="Verificado",IF(J36<='Tablas AR'!$B$22,"Verificado; revisar aceptación","Verificado; requiere tratamiento"),IF(J36<='Tablas AR'!$B$22,"Previsto; requiere prueba","Previsto; requiere tratamiento"))))) | N36: Nuevo tratamiento
A37: =IF(A12="","",A12) | B37: Mitigar | C37: Mantenimiento preventivo y plan de recuperación del servidor | D37: Infraestructura TI | E37: 45 | F37: Propuesto | G37: Supuesto didáctico: mantenimiento cotizado | H37: 1 | I37: 3 | J37: =IF(A37="","",IF(I12<>"Listo","Falta evaluación actual",IF(OR(COUNT(H37:I37)<>2,H37<1,H37>5,I37<1,I37>5,MOD(H37,1)<>0,MOD(I37,1)<>0),"Faltan P/I válidos",H37*I37))) | K37: =IF(ISNUMBER(J37),IF(J37<'Tablas AR'!$A$17,"Bajo",IF(J37<'Tablas AR'!$A$18,"Moderado",IF(J37<'Tablas AR'!$A$19,"Alto","Crítico"))),"") | L37: =IF(ISNUMBER(J37),(F12-J37)/F12,"") | M37: =IF(A37="","",IF(OR(B37="",C37="",D37="",NOT(ISNUMBER(E37)),E37<=0,F37="",G37="",N37=""),"Completar tratamiento y decisión",IF(NOT(ISNUMBER(J37)),"Completar evaluación",IF(F37="Verificado",IF(J37<='Tablas AR'!$B$22,"Verificado; revisar aceptación","Verificado; requiere tratamiento"),IF(J37<='Tablas AR'!$B$22,"Previsto; requiere prueba","Previsto; requiere tratamiento"))))) | N37: Solicitar aceptación
A38: =IF(A13="","",A13) | B38: Mitigar | C38: Enlace alternativo y procedimiento manual de matrícula | D38: Infraestructura TI | E38: 60 | F38: Propuesto | G38: Supuesto didáctico: formularios impresos y capacitación | H38: 2 | I38: 2 | J38: =IF(A38="","",IF(I13<>"Listo","Falta evaluación actual",IF(OR(COUNT(H38:I38)<>2,H38<1,H38>5,I38<1,I38>5,MOD(H38,1)<>0,MOD(I38,1)<>0),"Faltan P/I válidos",H38*I38))) | K38: =IF(ISNUMBER(J38),IF(J38<'Tablas AR'!$A$17,"Bajo",IF(J38<'Tablas AR'!$A$18,"Moderado",IF(J38<'Tablas AR'!$A$19,"Alto","Crítico"))),"") | L38: =IF(ISNUMBER(J38),(F13-J38)/F13,"") | M38: =IF(A38="","",IF(OR(B38="",C38="",D38="",NOT(ISNUMBER(E38)),E38<=0,F38="",G38="",N38=""),"Completar tratamiento y decisión",IF(NOT(ISNUMBER(J38)),"Completar evaluación",IF(F38="Verificado",IF(J38<='Tablas AR'!$B$22,"Verificado; revisar aceptación","Verificado; requiere tratamiento"),IF(J38<='Tablas AR'!$B$22,"Previsto; requiere prueba","Previsto; requiere tratamiento"))))) | N38: Solicitar aceptación
A39: =IF(A14="","",A14) | B39: Mitigar | C39: Cifrado de disco en portátiles y control físico de equipos | D39: Administración del Sistema | E39: 30 | F39: Propuesto | G39: Supuesto didáctico: cifrado activado en 2 equipos | H39: 1 | I39: 3 | J39: =IF(A39="","",IF(I14<>"Listo","Falta evaluación actual",IF(OR(COUNT(H39:I39)<>2,H39<1,H39>5,I39<1,I39>5,MOD(H39,1)<>0,MOD(I39,1)<>0),"Faltan P/I válidos",H39*I39))) | K39: =IF(ISNUMBER(J39),IF(J39<'Tablas AR'!$A$17,"Bajo",IF(J39<'Tablas AR'!$A$18,"Moderado",IF(J39<'Tablas AR'!$A$19,"Alto","Crítico"))),"") | L39: =IF(ISNUMBER(J39),(F14-J39)/F14,"") | M39: =IF(A39="","",IF(OR(B39="",C39="",D39="",NOT(ISNUMBER(E39)),E39<=0,F39="",G39="",N39=""),"Completar tratamiento y decisión",IF(NOT(ISNUMBER(J39)),"Completar evaluación",IF(F39="Verificado",IF(J39<='Tablas AR'!$B$22,"Verificado; revisar aceptación","Verificado; requiere tratamiento"),IF(J39<='Tablas AR'!$B$22,"Previsto; requiere prueba","Previsto; requiere tratamiento"))))) | N39: Solicitar aceptación
A40: =IF(A15="","",A15) | B40: Mitigar | C40: Ventana de pruebas previas y plan de reversión documentado | D40: Administración del Sistema | E40: 15 | F40: Propuesto | G40: Supuesto didáctico: entorno de pruebas separado | H40: 2 | I40: 2 | J40: =IF(A40="","",IF(I15<>"Listo","Falta evaluación actual",IF(OR(COUNT(H40:I40)<>2,H40<1,H40>5,I40<1,I40>5,MOD(H40,1)<>0,MOD(I40,1)<>0),"Faltan P/I válidos",H40*I40))) | K40: =IF(ISNUMBER(J40),IF(J40<'Tablas AR'!$A$17,"Bajo",IF(J40<'Tablas AR'!$A$18,"Moderado",IF(J40<'Tablas AR'!$A$19,"Alto","Crítico"))),"") | L40: =IF(ISNUMBER(J40),(F15-J40)/F15,"") | M40: =IF(A40="","",IF(OR(B40="",C40="",D40="",NOT(ISNUMBER(E40)),E40<=0,F40="",G40="",N40=""),"Completar tratamiento y decisión",IF(NOT(ISNUMBER(J40)),"Completar evaluación",IF(F40="Verificado",IF(J40<='Tablas AR'!$B$22,"Verificado; revisar aceptación","Verificado; requiere tratamiento"),IF(J40<='Tablas AR'!$B$22,"Previsto; requiere prueba","Previsto; requiere tratamiento"))))) | N40: Solicitar aceptación
A41: =IF(A16="","",A16) | J41: =IF(A41="","",IF(I16<>"Listo","Falta evaluación actual",IF(OR(COUNT(H41:I41)<>2,H41<1,H41>5,I41<1,I41>5,MOD(H41,1)<>0,MOD(I41,1)<>0),"Faltan P/I válidos",H41*I41))) | K41: =IF(ISNUMBER(J41),IF(J41<'Tablas AR'!$A$17,"Bajo",IF(J41<'Tablas AR'!$A$18,"Moderado",IF(J41<'Tablas AR'!$A$19,"Alto","Crítico"))),"") | L41: =IF(ISNUMBER(J41),(F16-J41)/F16,"") | M41: =IF(A41="","",IF(OR(B41="",C41="",D41="",NOT(ISNUMBER(E41)),E41<=0,F41="",G41="",N41=""),"Completar tratamiento y decisión",IF(NOT(ISNUMBER(J41)),"Completar evaluación",IF(F41="Verificado",IF(J41<='Tablas AR'!$B$22,"Verificado; revisar aceptación","Verificado; requiere tratamiento"),IF(J41<='Tablas AR'!$B$22,"Previsto; requiere prueba","Previsto; requiere tratamiento")))))
A42: =IF(A17="","",A17) | J42: =IF(A42="","",IF(I17<>"Listo","Falta evaluación actual",IF(OR(COUNT(H42:I42)<>2,H42<1,H42>5,I42<1,I42>5,MOD(H42,1)<>0,MOD(I42,1)<>0),"Faltan P/I válidos",H42*I42))) | K42: =IF(ISNUMBER(J42),IF(J42<'Tablas AR'!$A$17,"Bajo",IF(J42<'Tablas AR'!$A$18,"Moderado",IF(J42<'Tablas AR'!$A$19,"Alto","Crítico"))),"") | L42: =IF(ISNUMBER(J42),(F17-J42)/F17,"") | M42: =IF(A42="","",IF(OR(B42="",C42="",D42="",NOT(ISNUMBER(E42)),E42<=0,F42="",G42="",N42=""),"Completar tratamiento y decisión",IF(NOT(ISNUMBER(J42)),"Completar evaluación",IF(F42="Verificado",IF(J42<='Tablas AR'!$B$22,"Verificado; revisar aceptación","Verificado; requiere tratamiento"),IF(J42<='Tablas AR'!$B$22,"Previsto; requiere prueba","Previsto; requiere tratamiento")))))
A43: =IF(A18="","",A18) | J43: =IF(A43="","",IF(I18<>"Listo","Falta evaluación actual",IF(OR(COUNT(H43:I43)<>2,H43<1,H43>5,I43<1,I43>5,MOD(H43,1)<>0,MOD(I43,1)<>0),"Faltan P/I válidos",H43*I43))) | K43: =IF(ISNUMBER(J43),IF(J43<'Tablas AR'!$A$17,"Bajo",IF(J43<'Tablas AR'!$A$18,"Moderado",IF(J43<'Tablas AR'!$A$19,"Alto","Crítico"))),"") | L43: =IF(ISNUMBER(J43),(F18-J43)/F18,"") | M43: =IF(A43="","",IF(OR(B43="",C43="",D43="",NOT(ISNUMBER(E43)),E43<=0,F43="",G43="",N43=""),"Completar tratamiento y decisión",IF(NOT(ISNUMBER(J43)),"Completar evaluación",IF(F43="Verificado",IF(J43<='Tablas AR'!$B$22,"Verificado; revisar aceptación","Verificado; requiere tratamiento"),IF(J43<='Tablas AR'!$B$22,"Previsto; requiere prueba","Previsto; requiere tratamiento")))))
A44: =IF(A19="","",A19) | J44: =IF(A44="","",IF(I19<>"Listo","Falta evaluación actual",IF(OR(COUNT(H44:I44)<>2,H44<1,H44>5,I44<1,I44>5,MOD(H44,1)<>0,MOD(I44,1)<>0),"Faltan P/I válidos",H44*I44))) | K44: =IF(ISNUMBER(J44),IF(J44<'Tablas AR'!$A$17,"Bajo",IF(J44<'Tablas AR'!$A$18,"Moderado",IF(J44<'Tablas AR'!$A$19,"Alto","Crítico"))),"") | L44: =IF(ISNUMBER(J44),(F19-J44)/F19,"") | M44: =IF(A44="","",IF(OR(B44="",C44="",D44="",NOT(ISNUMBER(E44)),E44<=0,F44="",G44="",N44=""),"Completar tratamiento y decisión",IF(NOT(ISNUMBER(J44)),"Completar evaluación",IF(F44="Verificado",IF(J44<='Tablas AR'!$B$22,"Verificado; revisar aceptación","Verificado; requiere tratamiento"),IF(J44<='Tablas AR'!$B$22,"Previsto; requiere prueba","Previsto; requiere tratamiento")))))
A45: =IF(A20="","",A20) | J45: =IF(A45="","",IF(I20<>"Listo","Falta evaluación actual",IF(OR(COUNT(H45:I45)<>2,H45<1,H45>5,I45<1,I45>5,MOD(H45,1)<>0,MOD(I45,1)<>0),"Faltan P/I válidos",H45*I45))) | K45: =IF(ISNUMBER(J45),IF(J45<'Tablas AR'!$A$17,"Bajo",IF(J45<'Tablas AR'!$A$18,"Moderado",IF(J45<'Tablas AR'!$A$19,"Alto","Crítico"))),"") | L45: =IF(ISNUMBER(J45),(F20-J45)/F20,"") | M45: =IF(A45="","",IF(OR(B45="",C45="",D45="",NOT(ISNUMBER(E45)),E45<=0,F45="",G45="",N45=""),"Completar tratamiento y decisión",IF(NOT(ISNUMBER(J45)),"Completar evaluación",IF(F45="Verificado",IF(J45<='Tablas AR'!$B$22,"Verificado; revisar aceptación","Verificado; requiere tratamiento"),IF(J45<='Tablas AR'!$B$22,"Previsto; requiere prueba","Previsto; requiere tratamiento")))))
A46: =IF(A21="","",A21) | J46: =IF(A46="","",IF(I21<>"Listo","Falta evaluación actual",IF(OR(COUNT(H46:I46)<>2,H46<1,H46>5,I46<1,I46>5,MOD(H46,1)<>0,MOD(I46,1)<>0),"Faltan P/I válidos",H46*I46))) | K46: =IF(ISNUMBER(J46),IF(J46<'Tablas AR'!$A$17,"Bajo",IF(J46<'Tablas AR'!$A$18,"Moderado",IF(J46<'Tablas AR'!$A$19,"Alto","Crítico"))),"") | L46: =IF(ISNUMBER(J46),(F21-J46)/F21,"") | M46: =IF(A46="","",IF(OR(B46="",C46="",D46="",NOT(ISNUMBER(E46)),E46<=0,F46="",G46="",N46=""),"Completar tratamiento y decisión",IF(NOT(ISNUMBER(J46)),"Completar evaluación",IF(F46="Verificado",IF(J46<='Tablas AR'!$B$22,"Verificado; revisar aceptación","Verificado; requiere tratamiento"),IF(J46<='Tablas AR'!$B$22,"Previsto; requiere prueba","Previsto; requiere tratamiento")))))
A47: =IF(A22="","",A22) | J47: =IF(A47="","",IF(I22<>"Listo","Falta evaluación actual",IF(OR(COUNT(H47:I47)<>2,H47<1,H47>5,I47<1,I47>5,MOD(H47,1)<>0,MOD(I47,1)<>0),"Faltan P/I válidos",H47*I47))) | K47: =IF(ISNUMBER(J47),IF(J47<'Tablas AR'!$A$17,"Bajo",IF(J47<'Tablas AR'!$A$18,"Moderado",IF(J47<'Tablas AR'!$A$19,"Alto","Crítico"))),"") | L47: =IF(ISNUMBER(J47),(F22-J47)/F22,"") | M47: =IF(A47="","",IF(OR(B47="",C47="",D47="",NOT(ISNUMBER(E47)),E47<=0,F47="",G47="",N47=""),"Completar tratamiento y decisión",IF(NOT(ISNUMBER(J47)),"Completar evaluación",IF(F47="Verificado",IF(J47<='Tablas AR'!$B$22,"Verificado; revisar aceptación","Verificado; requiere tratamiento"),IF(J47<='Tablas AR'!$B$22,"Previsto; requiere prueba","Previsto; requiere tratamiento")))))
A48: =IF(A23="","",A23) | J48: =IF(A48="","",IF(I23<>"Listo","Falta evaluación actual",IF(OR(COUNT(H48:I48)<>2,H48<1,H48>5,I48<1,I48>5,MOD(H48,1)<>0,MOD(I48,1)<>0),"Faltan P/I válidos",H48*I48))) | K48: =IF(ISNUMBER(J48),IF(J48<'Tablas AR'!$A$17,"Bajo",IF(J48<'Tablas AR'!$A$18,"Moderado",IF(J48<'Tablas AR'!$A$19,"Alto","Crítico"))),"") | L48: =IF(ISNUMBER(J48),(F23-J48)/F23,"") | M48: =IF(A48="","",IF(OR(B48="",C48="",D48="",NOT(ISNUMBER(E48)),E48<=0,F48="",G48="",N48=""),"Completar tratamiento y decisión",IF(NOT(ISNUMBER(J48)),"Completar evaluación",IF(F48="Verificado",IF(J48<='Tablas AR'!$B$22,"Verificado; revisar aceptación","Verificado; requiere tratamiento"),IF(J48<='Tablas AR'!$B$22,"Previsto; requiere prueba","Previsto; requiere tratamiento")))))
A49: =IF(A24="","",A24) | J49: =IF(A49="","",IF(I24<>"Listo","Falta evaluación actual",IF(OR(COUNT(H49:I49)<>2,H49<1,H49>5,I49<1,I49>5,MOD(H49,1)<>0,MOD(I49,1)<>0),"Faltan P/I válidos",H49*I49))) | K49: =IF(ISNUMBER(J49),IF(J49<'Tablas AR'!$A$17,"Bajo",IF(J49<'Tablas AR'!$A$18,"Moderado",IF(J49<'Tablas AR'!$A$19,"Alto","Crítico"))),"") | L49: =IF(ISNUMBER(J49),(F24-J49)/F24,"") | M49: =IF(A49="","",IF(OR(B49="",C49="",D49="",NOT(ISNUMBER(E49)),E49<=0,F49="",G49="",N49=""),"Completar tratamiento y decisión",IF(NOT(ISNUMBER(J49)),"Completar evaluación",IF(F49="Verificado",IF(J49<='Tablas AR'!$B$22,"Verificado; revisar aceptación","Verificado; requiere tratamiento"),IF(J49<='Tablas AR'!$B$22,"Previsto; requiere prueba","Previsto; requiere tratamiento")))))
A50: =IF(A25="","",A25) | J50: =IF(A50="","",IF(I25<>"Listo","Falta evaluación actual",IF(OR(COUNT(H50:I50)<>2,H50<1,H50>5,I50<1,I50>5,MOD(H50,1)<>0,MOD(I50,1)<>0),"Faltan P/I válidos",H50*I50))) | K50: =IF(ISNUMBER(J50),IF(J50<'Tablas AR'!$A$17,"Bajo",IF(J50<'Tablas AR'!$A$18,"Moderado",IF(J50<'Tablas AR'!$A$19,"Alto","Crítico"))),"") | L50: =IF(ISNUMBER(J50),(F25-J50)/F25,"") | M50: =IF(A50="","",IF(OR(B50="",C50="",D50="",NOT(ISNUMBER(E50)),E50<=0,F50="",G50="",N50=""),"Completar tratamiento y decisión",IF(NOT(ISNUMBER(J50)),"Completar evaluación",IF(F50="Verificado",IF(J50<='Tablas AR'!$B$22,"Verificado; revisar aceptación","Verificado; requiere tratamiento"),IF(J50<='Tablas AR'!$B$22,"Previsto; requiere prueba","Previsto; requiere tratamiento")))))
A53: Resumen actual | B53: Cantidad
A54: Bajo | B54: =COUNTIF($G$6:$G$25,A54) -> 0
A55: Moderado | B55: =COUNTIF($G$6:$G$25,A55) -> 0
...
